Workbook
Name TGT_MIN: '集計・設定'!$C$4
Name TGT_MAX: '集計・設定'!$C$5

Sheet 集計・設定
A1: 自治体営業リスト（統合版） 地域公共交通計画・環境基本計画 終期一覧 集計・設定
A3: ■ 営業対象とする終期（令和年度）
B4: 下限 | C4: 9 | D4: ▼プルダウンで選ぶと全シートの判定（◎）と終期セルの色が切り替わります。例：R10年度に終わる計画も見る→上限を10に／R10だけ見る→下限・上限とも10に。
B5: 上限 | C5: 9 | D5: R8年度で終わる計画は作成中のため対象外（初期値は下限9・上限9）。終期セルの色：緑＝対象年度、橙＝上限の翌年度（次の営業候補）。
A7: ■ 県別の集計
B8: 県 | C8: 市町村数 | D8: ◎ 営業 | E8: △ 着手済・要確認 | F8: ？ 期間要確認 | G8: ✕ 対象外 | H8: 未調査 | I8: 一部のみ調査
B9: 青森県 | C9: =COUNTA('青森県'!$C$4:$C$43) | D9: =COUNTIF('青森県'!$C$4:$C$43,"◎ 営業") | E9: =COUNTIF('青森県'!$C$4:$C$43,"△ 着手済・要確認") | F9: =COUNTIF('青森県'!$C$4:$C$43,"？ 期間要確認") | G9: =COUNTIF('青森県'!$C$4:$C$43,"✕ 対象外") | H9: =COUNTIF('青森県'!$S$4:$S$43,"未調査") | I9: =COUNTIF('青森県'!$S$4:$S$43,"交通のみ調査")+COUNTIF('青森県'!$S$4:$S$43,"環境のみ調査")
B10: 岩手県 | C10: =COUNTA('岩手県'!$C$4:$C$36) | D10: =COUNTIF('岩手県'!$C$4:$C$36,"◎ 営業") | E10: =COUNTIF('岩手県'!$C$4:$C$36,"△ 着手済・要確認") | F10: =COUNTIF('岩手県'!$C$4:$C$36,"？ 期間要確認") | G10: =COUNTIF('岩手県'!$C$4:$C$36,"✕ 対象外") | H10: =COUNTIF('岩手県'!$S$4:$S$36,"未調査") | I10: =COUNTIF('岩手県'!$S$4:$S$36,"交通のみ調査")+COUNTIF('岩手県'!$S$4:$S$36,"環境のみ調査")
B11: 宮城県 | C11: =COUNTA('宮城県'!$C$4:$C$38) | D11: =COUNTIF('宮城県'!$C$4:$C$38,"◎ 営業") | E11: =COUNTIF('宮城県'!$C$4:$C$38,"△ 着手済・要確認") | F11: =COUNTIF('宮城県'!$C$4:$C$38,"？ 期間要確認") | G11: =COUNTIF('宮城県'!$C$4:$C$38,"✕ 対象外") | H11: =COUNTIF('宮城県'!$S$4:$S$38,"未調査") | I11: =COUNTIF('宮城県'!$S$4:$S$38,"交通のみ調査")+COUNTIF('宮城県'!$S$4:$S$38,"環境のみ調査")
B12: 秋田県 | C12: =COUNTA('秋田県'!$C$4:$C$28) | D12: =COUNTIF('秋田県'!$C$4:$C$28,"◎ 営業") | E12: =COUNTIF('秋田県'!$C$4:$C$28,"△ 着手済・要確認") | F12: =COUNTIF('秋田県'!$C$4:$C$28,"？ 期間要確認") | G12: =COUNTIF('秋田県'!$C$4:$C$28,"✕ 対象外") | H12: =COUNTIF('秋田県'!$S$4:$S$28,"未調査") | I12: =COUNTIF('秋田県'!$S$4:$S$28,"交通のみ調査")+COUNTIF('秋田県'!$S$4:$S$28,"環境のみ調査")
B13: 山形県 | C13: =COUNTA('山形県'!$C$4:$C$38) | D13: =COUNTIF('山形県'!$C$4:$C$38,"◎ 営業") | E13: =COUNTIF('山形県'!$C$4:$C$38,"△ 着手済・要確認") | F13: =COUNTIF('山形県'!$C$4:$C$38,"？ 期間要確認") | G13: =COUNTIF('山形県'!$C$4:$C$38,"✕ 対象外") | H13: =COUNTIF('山形県'!$S$4:$S$38,"未調査") | I13: =COUNTIF('山形県'!$S$4:$S$38,"交通のみ調査")+COUNTIF('山形県'!$S$4:$S$38,"環境のみ調査")
B14: 福島県 | C14: =COUNTA('福島県'!$C$4:$C$62) | D14: =COUNTIF('福島県'!$C$4:$C$62,"◎ 営業") | E14: =COUNTIF('福島県'!$C$4:$C$62,"△ 着手済・要確認") | F14: =COUNTIF('福島県'!$C$4:$C$62,"？ 期間要確認") | G14: =COUNTIF('福島県'!$C$4:$C$62,"✕ 対象外") | H14: =COUNTIF('福島県'!$S$4:$S$62,"未調査") | I14: =COUNTIF('福島県'!$S$4:$S$62,"交通のみ調査")+COUNTIF('福島県'!$S$4:$S$62,"環境のみ調査")
B15: 茨城県 | C15: =COUNTA('茨城県'!$C$4:$C$47) | D15: =COUNTIF('茨城県'!$C$4:$C$47,"◎ 営業") | E15: =COUNTIF('茨城県'!$C$4:$C$47,"△ 着手済・要確認") | F15: =COUNTIF('茨城県'!$C$4:$C$47,"？ 期間要確認") | G15: =COUNTIF('茨城県'!$C$4:$C$47,"✕ 対象外") | H15: =COUNTIF('茨城県'!$S$4:$S$47,"未調査") | I15: =COUNTIF('茨城県'!$S$4:$S$47,"交通のみ調査")+COUNTIF('茨城県'!$S$4:$S$47,"環境のみ調査")
B16: 栃木県 | C16: =COUNTA('栃木県'!$C$4:$C$28) | D16: =COUNTIF('栃木県'!$C$4:$C$28,"◎ 営業") | E16: =COUNTIF('栃木県'!$C$4:$C$28,"△ 着手済・要確認") | F16: =COUNTIF('栃木県'!$C$4:$C$28,"？ 期間要確認") | G16: =COUNTIF('栃木県'!$C$4:$C$28,"✕ 対象外") | H16: =COUNTIF('栃木県'!$S$4:$S$28,"未調査") | I16: =COUNTIF('栃木県'!$S$4:$S$28,"交通のみ調査")+COUNTIF('栃木県'!$S$4:$S$28,"環境のみ調査")
B17: 群馬県 | C17: =COUNTA('群馬県'!$C$4:$C$38) | D17: =COUNTIF('群馬県'!$C$4:$C$38,"◎ 営業") | E17: =COUNTIF('群馬県'!$C$4:$C$38,"△ 着手済・要確認") | F17: =COUNTIF('群馬県'!$C$4:$C$38,"？ 期間要確認") | G17: =COUNTIF('群馬県'!$C$4:$C$38,"✕ 対象外") | H17: =COUNTIF('群馬県'!$S$4:$S$38,"未調査") | I17: =COUNTIF('群馬県'!$S$4:$S$38,"交通のみ調査")+COUNTIF('群馬県'!$S$4:$S$38,"環境のみ調査")
B18: 宮崎県 | C18: =COUNTA('宮崎県'!$C$4:$C$29) | D18: =COUNTIF('宮崎県'!$C$4:$C$29,"◎ 営業") | E18: =COUNTIF('宮崎県'!$C$4:$C$29,"△ 着手済・要確認") | F18: =COUNTIF('宮崎県'!$C$4:$C$29,"？ 期間要確認") | G18: =COUNTIF('宮崎県'!$C$4:$C$29,"✕ 対象外") | H18: =COUNTIF('宮崎県'!$S$4:$S$29,"未調査") | I18: =COUNTIF('宮崎県'!$S$4:$S$29,"交通のみ調査")+COUNTIF('宮崎県'!$S$4:$S$29,"環境のみ調査")
B19: 合計 | C19: =SUM(C9:C18) | D19: =SUM(D9:D18) | E19: =SUM(E9:E18) | F19: =SUM(F9:F18) | G19: =SUM(G9:G18) | H19: =SUM(H9:H18) | I19: =SUM(I9:I18)
A21: ■ 判定の見方
A22: ◎ 営業：どちらかの計画の終期が対象年度（初期値R9）で、次の計画の作業は見つかっていない
A23: △ 着手済・要確認：終期は対象年度だが、次期計画の策定業務委託やパブコメをすでに確認済。委託先が決まっている可能性が高い
A24: ？ 期間要確認：終期がわからないため判定できない
A25: ✕ 対象外：終期が対象年度の外（R8以前は作成中または終了、R10以降は先）、または新計画を策定済
A26: －：その計画がない（環境基本計画を作っていない町村など）
A28: ■ 入力する列
A29: 各県シートの「終期(令和年度)」と「改定状況」（未確認／着手済／策定済／計画なし）を直すと、判定が自動で変わります。
A30: 「未確認」は、改定の動きが検索で見つからなかったという意味です。動きがないと確かめたわけではありません。
A31: 確度：確認済＝検索結果の本文に期間が書かれていた／推定＝策定時期などから推測（終期のセルは茶色の斜体）／不明＝確認できなかった
A33: ■ 国交省一覧との照合（T列）
A34: 国土交通省「地域公共交通計画の作成状況一覧」（令和8年5月末時点）と照合。掲載＝計画作成済み、期間満了＝一覧で灰色（計画期間が満了）。一覧には計画期間の記載がないため、終期は各計画書で確認。
... A42: ■ シート一覧（クリックで移動）
B43: 青森県
B44: 岩手県
B45: 宮城県
B46: 秋田県
B47: 山形県
B48: 福島県
B49: 茨城県
B50: 栃木県
B51: 群馬県
B52: 宮崎県
...

Sheet 青森県
A1: 青森県 地域公共交通計画・環境基本計画の終期一覧（2026年9月30日時点の調査）
A2: ="営業判定の対象：終期 R"&TGT_MIN&"〜R"&TGT_MAX&"年度 →◎（着手済は△、期間不明は？）。終期セルの色：緑＝対象年度／橙＝その翌年度（次の候補）。対象年度は「集計・設定」シートのC4・C5のプルダウンで切替。"
A3: No | B3: 市町村 | C3: 営業判定 | D3: 交通判定 | E3: 環境判定 | F3: 地域公共交通計画 | G3: 交通 計画期間 | H3: 交通 終期(令和年度) | I3: 交通 確度 | J3: 交通 改定状況 | K3: 交通 計画リンク（エビデンス） | L3: 環境基本計画 | M3: 環境 計画期間 | N3: 環境 終期(令和年度) | O3: 環境 確度 | P3: 環境 改定状況 | Q3: 環境 計画リンク（エビデンス） | R3: 注釈（改定作業の状況など） | S3: 調査状況 | T3: 国交省一覧(R8.5末) | U3: 営業メモ | V3: 位置図
A4: 1 | B4: 青森市 | C4: =IF(OR(D4="◎",E4="◎"),"◎ 営業",IF(OR(D4="△",E4="△"),"△ 着手済・要確認",IF(OR(D4="？",E4="？"),"？ 期間要確認","✕ 対象外"))) | D4: =IF(J4="計画なし","－",IF(J4="策定済","✕",IF(H4="","？",IF(AND(H4>=TGT_MIN,H4<=TGT_MAX),IF(J4="着手済","△","◎"),"✕")))) | E4: =IF(P4="計画なし","－",IF(P4="策定済","✕",IF(N4="","？",IF(AND(N4>=TGT_MIN,N4<=TGT_MAX),IF(P4="着手済","△","◎"),"✕")))) | F4: 青森市地域公共交通計画 | G4: R6〜R10 | H4: 10 | I4: 確認済 | J4: 未確認 | K4: https://www.city.aomori.aomori.jp/somu/shiseijouhou/jyouhou-koukai/tyougi/documents/tiikikoutuumoukeikaku.pdf | L4: 青森市環境基本計画（令和7年12月制定の青森市環境基本条例第8条に基づき策定中） | M4: R8〜R10 | N4: 10 | O4: 確認済 | P4: 着手済 | Q4: https://www.city.aomori.aomori.jp/_res/projects/default_project/_page_/001/011/090/05_080722siryou3.pdf | R4: 環境基本計画は新条例（R7.12）に基づく新規策定中。R8.7.22環境審議会資料によるとR8.10素案審議→R8.12パブコメ→R9.2計画案審議→策定予定（期間は総合計画前期基本計画終期に合わせR10まで）。関連: https://www.city.aomori.aomori.jp/_res/projects/default_project/_page_/001/009/192/080220anken1.pdf 。交通計画URLは市の審議会資料PDF（計画本体ページは未確認）。 | S4: 調査済 | T4: 掲載
A5: 2 | B5: 弘前市 | C5: =IF(OR(D5="◎",E5="◎"),"◎ 営業",IF(OR(D5="△",E5="△"),"△ 着手済・要確認",IF(OR(D5="？",E5="？"),"？ 期間要確認","✕ 対象外"))) | D5: =IF(J5="計画なし","－",IF(J5="策定済","✕",IF(H5="","？",IF(AND(H5>=TGT_MIN,H5<=TGT_MAX),IF(J5="着手済","△","◎"),"✕")))) | E5: =IF(P5="計画なし","－",IF(P5="策定済","✕",IF(N5="","？",IF(AND(N5>=TGT_MIN,N5<=TGT_MAX),IF(P5="着手済","△","◎"),"✕")))) | F5: 弘前市地域公共交通計画 | G5: R6〜R10 | H5: 10 | I5: 確認済 | J5: 未確認 | K5: https://www.city.hirosaki.aomori.jp/jouhou/keikaku/kokyokotu/kotsukeikaku.pdf | L5: 第3次弘前市環境基本計画 | M5: R3〜R12 | N5: 12 | O5: 推定 | P5: 未確認 | Q5: https://www.city.hirosaki.aomori.jp/jouhou/keikaku/2021-0401-kankyoukihon.html | R5: 環境：R3.3策定（改訂）の記載は資料編 https://city.hirosaki.aomori.jp/jouhou/keikaku/files/shiryouhen.pdf で示唆されるが、期間は今回の検索でも確認できず推定のまま。 | S5: 調査済 | T5: 掲載
A6: 3 | B6: 八戸市 | C6: =IF(OR(D6="◎",E6="◎"),"◎ 営業",IF(OR(D6="△",E6="△"),"△ 着手済・要確認",IF(OR(D6="？",E6="？"),"？ 期間要確認","✕ 対象外"))) | D6: =IF(J6="計画なし","－",IF(J6="策定済","✕",IF(H6="","？",IF(AND(H6>=TGT_MIN,H6<=TGT_MAX),IF(J6="着手済","△","◎"),"✕")))) | E6: =IF(P6="計画なし","－",IF(P6="策定済","✕",IF(N6="","？",IF(AND(N6>=TGT_MIN,N6<=TGT_MAX),IF(P6="着手済","△","◎"),"✕")))) | F6: 八戸圏域地域公共交通計画（広域） | G6: R5〜R10 | H6: 10 | I6: 確認済 | J6: 未確認 | K6: https://wwwtb.mlit.go.jp/tohoku/content/000181287.pdf | L6: 第3次八戸市環境基本計画 | M6: R5〜R14 | N6: 14 | O6: 推定 | P6: 未確認 | Q6: https://www.city.hachinohe.aomori.jp/gyoseijoho/keikaku_plan/kurashi_tetsuzuki/1/1/7959.html | R6: 環境：今回の検索でも期間確認できず推定のまま。関連：第2次八戸市地球温暖化対策実行計画区域施策編 https://www.city.hachinohe.aomori.jp/gyoseijoho/keikaku_plan/kurashi_tetsuzuki/1/1/7961.html 。 | S6: 調査済 | T6: 掲載（広域：八戸圏域）／期間満了
A7: 4 | B7: 黒石市 | C7: =IF(OR(D7="◎",E7="◎"),"◎ 営業",IF(OR(D7="△",E7="△"),"△ 着手済・要確認",IF(OR(D7="？",E7="？"),"？ 期間要確認","✕ 対象外"))) | D7: =IF(J7="計画なし","－",IF(J7="策定済","✕",IF(H7="","？",IF(AND(H7>=TGT_MIN,H7<=TGT_MAX),IF(J7="着手済","△","◎"),"✕")))) | E7: =IF(P7="計画なし","－",IF(P7="策定済","✕",IF(N7="","？",IF(AND(N7>=TGT_MIN,N7<=TGT_MAX),IF(P7="着手済","△","◎"),"✕")))) | F7: 黒石市地域公共交通計画 | G7: R7〜R11 | H7: 11 | I7: 確認済 | J7: 策定済 | K7: http://www.city.kuroishi.aomori.jp/shisei/keikaku/2025-0523-1102-33.html | L7: 第二次黒石市環境基本計画 | M7: 不明 | O7: 不明 | P7: 未確認 | Q7: http://www.city.kuroishi.aomori.jp/shisei/keikaku/kankyou-kihon-keikaku.html | R7: 交通：R7.3策定、R7〜R11の5年間。R1.10策定の地域公共交通網形成計画を継承。策定支援業務委託はR6.5公告（NJSS https://www2.njss.info/offers/view/29276332）。環境：第二次計画のページは確認したが計画期間は検索結果で確認できず（要確認）。 【追加調査 2026-10】環境：一般検索・市サイト限定検索（計4回）とも第二次黒石市環境基本計画のページ（http://www.city.kuroishi.aomori.jp/shisei/keikaku/kankyou-kihon-keikaku.html）は出るが計画期間の記載は検索結果に出ず。検索要約に『第3次黒石市環境基本計画』が掲載されている旨の言及が2回あったが、完全一致検索ではヒットせず未確認（同ページに第3次が追加された可能性あり、要確認）。R2.3頃のパブコメページ http://www.city.kuroishi.aomori.jp/shisei/comments/2020-0327-2054-15.html あり（内容未確認）。市サイトはWebFetchブロック。確認日2026-10-02。 | S7: 調査済 | T7: 掲載
A8: 5 | B8: 五所川原市 | C8: =IF(OR(D8="◎",E8="◎"),"◎ 営業",IF(OR(D8="△",E8="△"),"△ 着手済・要確認",IF(OR(D8="？",E8="？"),"？ 期間要確認","✕ 対象外"))) | D8: =IF(J8="計画なし","－",IF(J8="策定済","✕",IF(H8="","？",IF(AND(H8>=TGT_MIN,H8<=TGT_MAX),IF(J8="着手済","△","◎"),"✕")))) | E8: =IF(P8="計画なし","－",IF(P8="策定済","✕",IF(N8="","？",IF(AND(N8>=TGT_MIN,N8<=TGT_MAX),IF(P8="着手済","△","◎"),"✕")))) | F8: 五所川原市地域公共交通計画 | G8: R5〜R10 | H8: 10 | I8: 確認済 | J8: 未確認 | K8: https://www.city.goshogawara.lg.jp/kurashi/machi/chiikikoukyokoutsukeikaku.html | M8: 不明 | O8: 不明 | P8: 未確認 | R8: 交通：R5.6策定（パブコメR5.4.17〜5.16）。期間は検索結果で未確認のため5年と仮定した推定値（要確認）。R6.3に五所川原市地域公共交通推進計画（R6〜R10、確認済 https://www.city.goshogawara.lg.jp/jouhou/keikaku/files/koutuu_suisin.pdf）。H28.3網形成計画・H30.3再編実施計画あり。環境：環境基本計画は検索で見当たらず。代替として五所川原市地球温暖化対策実行計画（区域施策編）が存在する模様（https://www.city.goshogawara.lg.jp/kurashi/kurashi/files/planR2_gaiyouban.pdf の可能性）。事務事業編相当は環境保全率先行動計画（H21〜H25）。 【ファクトチェック 2026-10-01: 誤り】確認期間: R5〜R10（令和5年6月策定、令和10年度までの取組を定める）／次期: 確認できず（次期計画の策定支援業務・パブコメは見当たらず。概要版が gaiyouR7.1/R7.6/R8.1 と更新されており、R8.1時点で計画の変更あり）／根拠: https://www.city.goshogawara.lg.jp/kurashi/machi/files/suishinnkeikaku-gaiyou.ver.pdf 【追加調査 2026-10】環境：市サイト限定検索・完全一致検索とも『五所川原市環境基本計画』『環境基本条例』は見当たらず。環境関連は一般廃棄物処理基本計画（R3〜R12, https://www.city.goshogawara.lg.jp/kurashi/kurashi/files/pianR2.pdf）、生活排水基本計画、環境保全率先行動計画、ゼロカーボンシティ宣言のみヒット。計画なしの明示的根拠はないため未確認のまま。確認日2026-10-02。 | S8: 交通のみ調査 | T8: 掲載
A9: 6 | B9: 十和田市 | C9: =IF(OR(D9="◎",E9="◎"),"◎ 営業",IF(OR(D9="△",E9="△"),"△ 着手済・要確認",IF(OR(D9="？",E9="？"),"？ 期間要確認","✕ 対象外"))) | D9: =IF(J9="計画なし","－",IF(J9="策定済","✕",IF(H9="","？",IF(AND(H9>=TGT_MIN,H9<=TGT_MAX),IF(J9="着手済","△","◎"),"✕")))) | E9: =IF(P9="計画なし","－",IF(P9="策定済","✕",IF(N9="","？",IF(AND(N9>=TGT_MIN,N9<=TGT_MAX),IF(P9="着手済","△","◎"),"✕")))) | F9: 十和田市地域公共交通計画 | G9: R5〜R9 | H9: 9 | I9: 確認済 | J9: 未確認 | K9: https://www.city.towada.lg.jp/kurashi/koutsu/files/keikaku.pdf | M9: 不明 | O9: 不明 | P9: 計画なし | R9: 交通：計画期間R5〜R9（5か年、検索結果で確認）。概要版 https://www.city.towada.lg.jp/kurashi/koutsu/files/gaiyouban.pdf 。策定支援業務仕様書 https://www.city.towada.lg.jp/kurashi/koutsu/files/shiyousyo.pdf あり（日付不明、現行計画策定時のものの可能性が高い。次期計画分かは要確認）。R9終了のため次期計画はR8〜R9に着手見込み。環境：環境基本計画は検索で見当たらず。R7.3に十和田市地球温暖化対策実行計画（区域施策編）策定（https://www.city.towada.lg.jp/shisei/gyousei/machidukuri/files/keikakugaiyouban.pdf）。 【ファクトチェック 2026-10-01: 正しい】確認期間: R5〜R9（2023〜2027年度）／次期: 確認できず（市サイト内検索で次期計画の策定支援プロポーザル・協議会審議は見当たらず。前回はR4年度にプロポーザル https://www.city.towada.lg.jp/kurashi/koutsuu/koutsuukeikaku.ht／根拠: https://www.city.towada.lg.jp/kurashi/koutsuu/files/keikaku.pdf 【追加調査 2026-10】環境：市サイト限定検索で環境基本計画は見当たらず。十和田市地球温暖化対策実行計画（区域施策編）案（2025/1/16版、計画期間2025〜2030年度 https://www.city.towada.lg.jp/shisei/gyousei/machidukuri/files/kuikisesakuhenan.pdf）の整合・連携先として第2次総合計画・都市計画MP・森林整備計画・国土強靭化計画・地域公共交通計画等が列挙されるが環境基本計画は挙がっておらず、環境分野の総合計画は区域施策編＋事務事業編（とわだエコ・オフィスプラン）で代替とみられる。確認日2026-10-02。 | S9: 調査済 | T9: 掲載 | U9: →メモ
A10: 7 | B10: 三沢市 | C10: =IF(OR(D10="◎",E10="◎"),"◎ 営業",IF(OR(D10="△",E10="△"),"△ 着手済・要確認",IF(OR(D10="？",E10="？"),"？ 期間要確認","✕ 対象外"))) | D10: =IF(J10="計画なし","－",IF(J10="策定済","✕",IF(H10="","？",IF(AND(H10>=TGT_MIN,H10<=TGT_MAX),IF(J10="着手済","△","◎"),"✕")))) | E10: =IF(P10="計画なし","－",IF(P10="策定済","✕",IF(N10="","？",IF(AND(N10>=TGT_MIN,N10<=TGT_MAX),IF(P10="着手済","△","◎"),"✕")))) | F10: 三沢市地域公共交通計画 | G10: 不明 | I10: 不明 | J10: 未確認 | K10: https://www.city.misawa.lg.jp/index.cfm/12,21981,57,254,html | L10: 第2次三沢市環境基本計画 | M10: H31〜R10 | N10: 10 | O10: 確認済 | P10: 未確認 | Q10: https://www.city.misawa.lg.jp/index.cfm/12,31881,c,html/31881/20181207-151357.pdf | R10: 交通：H28.3策定の地域公共交通網形成計画を継承して地域公共交通計画を策定（策定時期・期間は検索で確認できず）。素案ページ https://www.city.misawa.lg.jp/index.cfm/12,47680,79,350,html 。環境：第2次計画（素案表紙に2019.4〜2029.3と明記）。URLは素案PDF。 | S10: 調査済 | T10: 掲載
A11: 8 | B11: むつ市 | C11: =IF(OR(D11="◎",E11="◎"),"◎ 営業",IF(OR(D11="△",E11="△"),"△ 着手済・要確認",IF(OR(D11="？",E11="？"),"？ 期間要確認","✕ 対象外"))) | D11: =IF(J11="計画なし","－",IF(J11="策定済","✕",IF(H11="","？",IF(AND(H11>=TGT_MIN,H11<=TGT_MAX),IF(J11="着手済","△","◎"),"✕")))) | E11: =IF(P11="計画なし","－",IF(P11="策定済","✕",IF(N11="","？",IF(AND(N11>=TGT_MIN,N11<=TGT_MAX),IF(P11="着手済","△","◎"),"✕")))) | F11: 下北地域公共交通計画（広域） | G11: R7〜R11 | H11: 11 | I11: 確認済 | J11: 策定済 | K11: https://www.city.mutsu.lg.jp/government/katsudou/kyoudou/files/simokitatiikikoukyoukoutuukeikakusoann.pdf | M11: 不明 | O11: 不明 | P11: 未確認 | R11: 交通：下北地域公共交通総合連携協議会（むつ市・大間町・東通村・風間浦村・佐井村）がR7.3策定、2025〜2029。URLは素案PDF（パブコメR7.2.17〜3.3）。前計画はH30.3の下北地域公共交通網形成計画。市単独ではむつ市公共交通再編関連資料（2026）https://www.city.mutsu.lg.jp/kurashi/koutsu/koutsu_sisaku/files/mutsu_kokyokotsusaihen_2026.pdf あり（地域公共交通計画ではなく再編計画の可能性）。環境：環境基本計画は検索で見当たらず。第4期むつ市地球温暖化対策推進実行計画（事務事業編）R7.6策定（https://www.city.mutsu.lg.jp/kurashi/kankyo/kankyo/files/ondankakeikaku4.pdf）。 【追加調査 2026-10】環境：市サイト限定検索・完全一致検索（『むつ市環境基本計画』『むつ市環境基本条例』）とも該当なし。生活環境ページ https://www.city.mutsu.lg.jp/kurashi/kankyo/kankyo/ には地球温暖化対策推進実行計画・緑の基本計画等のみ。計画なしの明示的根拠はないため未確認のまま。確認日2026-10-02。 | S11: 交通のみ調査 | T11: 掲載（広域：下北地域）
A12: 9 | B12: つがる市 | C12: =IF(OR(D12="◎",E12="◎"),"◎ 営業",IF(OR(D12="△",E12="△"),"△ 着手済・要確認",IF(OR(D12="？",E12="？"),"？ 期間要確認","✕ 対象外"))) | D12: =IF(J12="計画なし","－",IF(J12="策定済","✕",IF(H12="","？",IF(AND(H12>=TGT_MIN,H12<=TGT_MAX),IF(J12="着手済","△","◎"),"✕")))) | E12: =IF(P12="計画なし","－",IF(P12="策定済","✕",IF(N12="","？",IF(AND(N12>=TGT_MIN,N12<=TGT_MAX),IF(P12="着手済","△","◎"),"✕")))) | G12: 不明 | I12: 不明 | J12: 未確認 | L12: 第2次つがる市環境基本計画 | M12: 不明 | O12: 不明 | P12: 未確認 | Q12: https://www.city.tsugaru.aomori.jp/soshiki/minsei/shimin/kankyoeisei/gomi/kankyoukihonkeikaku/10184.html | R12: 交通：地域公共交通計画は検索で確認できず。つがる市地域公共交通会議（H20.9設置）https://www.city.tsugaru.aomori.jp/soshiki/somu/tiikisousei/kikakusinnkou/kokyokotu/6434.html 。環境：第2次計画のページは確認、期間不明。区域施策編は西つがる3市町（つがる市・鰺ヶ沢町・深浦町）共同で策定（R6.3パブコメ https://www.town.fukaura.lg.jp/fixed_docs/2024032100017/）。 【追加調査 2026-10】環境：市サイト限定検索で『つがる市環境基本計画』一覧 https://www.city.tsugaru.aomori.jp/soshiki/minsei/shimin/kankyoeisei/gomi/kankyoukihonkeikaku/index.html と第2次計画ページ（10184.html、PDF約10MB公開、つがる市環境基本条例に基づく計画）を確認。計画期間・策定年は検索結果で確認できず（計4回検索）。市サイトはWebFetchブロック。確認日2026-10-02。 | S12: 環境のみ調査 | T12: 未掲載
A13: 10 | B13: 平川市 | C13: =IF(OR(D13="◎",E13="◎"),"◎ 営業",IF(OR(D13="△",E13="△"),"△ 着手済・要確認",IF(OR(D13="？",E13="？"),"？ 期間要確認","✕ 対象外"))) | D13: =IF(J13="計画なし","－",IF(J13="策定済","✕",IF(H13="","？",IF(AND(H13>=TGT_MIN,H13<=TGT_MAX),IF(J13="着手済","△","◎"),"✕")))) | E13: =IF(P13="計画なし","－",IF(P13="策定済","✕",IF(N13="","？",IF(AND(N13>=TGT_MIN,N13<=TGT_MAX),IF(P13="着手済","△","◎"),"✕")))) | F13: 平川市地域公共交通計画 | G13: 不明 | I13: 不明 | J13: 未確認 | K13: https://www.city.hirakawa.lg.jp/kurashi/keikaku/2021-0514-1007-25.html | L13: 平川市環境基本計画 | M13: H29〜R8 | N13: 8 | O13: 確認済 | P13: 未確認 | Q13: https://www.city.hirakawa.lg.jp/kurashi/keikaku/kankyokihonkeikaku.html | R13: 交通：R3（素案R3.3）策定、R4新庁舎開庁に合わせた再編のマスタープラン。期間は検索で確認できず（5年ならR3〜R7で既に終期到来の可能性、要確認）。策定業務プロポーザルページ https://www.city.hirakawa.lg.jp/shigoto/keiyaku/proposal/koukyoukoutsukeikaku_proposal.html（現行計画分か次期分か不明）。弘前圏域地域公共交通計画にも参加 https://www.city.hirakawa.lg.jp/kurashi/keikaku/hirosakikenikikoutsuukeikaku.html 。環境：H29〜R8の10年間でR8年度（今年度）終了。次期計画の策定業務公募等は検索で見つからず（要注視・有望）。 | S13: 調査済 | T13: 掲載
A14: 11 | B14: 平内町 | C14: =IF(OR(D14="◎",E14="◎"),"◎ 営業",IF(OR(D14="△",E14="△"),"△ 着手済・要確認",IF(OR(D14="？",E14="？"),"？ 期間要確認","✕ 対象外"))) | D14: =IF(J14="計画なし","－",IF(J14="策定済","✕",IF(H14="","？",IF(AND(H14>=TGT_MIN,H14<=TGT_MAX),IF(J14="着手済","△","◎"),"✕")))) | E14: =IF(P14="計画なし","－",IF(P14="策定済","✕",IF(N14="","？",IF(AND(N14>=TGT_MIN,N14<=TGT_MAX),IF(P14="着手済","△","◎"),"✕")))) | F14: 平内町地域公共交通計画 | G14: R4〜R8 | H14: 8 | I14: 推定 | J14: 未確認 | K14: https://www.town.hiranai.aomori.jp/chosei/machizukuri/3/1241.html | M14: 不明 | O14: 不明 | P14: 計画なし | R14: 交通：町HPに計画掲載、令和3年度策定と検索結果に記載（期間は未確認、5年計画と仮定しR4〜R8推定）。R8終了なら次期改定の動きに注意。環境基本計画は町/村名検索・公式サイト内検索で見当たらず（計画なしの確証はないため未確認）。 【追加調査 2026-10】環境：町サイト限定検索（town.hiranai.aomori.jp）で環境基本計画は見当たらず。町民課所管の環境関連計画として出るのは平内町地球温暖化対策実行計画（事務事業編、R2.3策定、R2〜R6）https://www.town.hiranai.aomori.jp/soshiki/chomin/1/3/1/chikyuondankataisaku01.html 、一般廃棄物処理基本計画、災害廃棄物処理計画のみ。環境分野は第六次平内町長期振興計画 https://www.town.hiranai.aomori.jp/soshiki/kikaku/1/1/2/414.html の分野別計画で扱う。町の計画一覧（まちづくり・計画 https://www.town.hiranai.aomori.jp/chosei/machizukuri/index.html ）にも無く計画なしと判断（明示的な記載ではない点に留意）。確認日2026-10-02。 | S14: 調査済 | T14: 掲載
A15: 12 | B15: 今別町 | C15: =IF(OR(D15="◎",E15="◎"),"◎ 営業",IF(OR(D15="△",E15="△"),"△ 着手済・要確認",IF(OR(D15="？",E15="？"),"？ 期間要確認","✕ 対象外"))) | D15: =IF(J15="計画なし","－",IF(J15="策定済","✕",IF(H15="","？",IF(AND(H15>=TGT_MIN,H15<=TGT_MAX),IF(J15="着手済","△","◎"),"✕")))) | E15: =IF(P15="計画なし","－",IF(P15="策定済","✕",IF(N15="","？",IF(AND(N15>=TGT_MIN,N15<=TGT_MAX),IF(P15="着手済","△","◎"),"✕")))) | F15: 今別町地域公共交通計画 | G15: R5〜R9 | H15: 9 | I15: 確認済 | J15: 未確認 | K15: https://www.town.imabetsu.lg.jp/gyousei/koukai/2023-0828-1639-1.html | M15: 不明 | O15: 不明 | P15: 未確認 | R15: 交通：策定支援業務プロポーザル2022-10（https://www.town.imabetsu.lg.jp/news/gyousei/2022-1017-1745-1.html）、計画公表ページ2023-08-28。期間は検索結果で未確認（R5〜R9推定）。JR津軽線蟹田〜三厩は2027年4月廃止・バス/乗合タクシー転換予定（NPO今別外ヶ浜交通）で計画見直しの可能性あり。環境基本計画は町/村名検索・公式サイト内検索で見当たらず（計画なしの確証はないため未確認）。 【ファクトチェック 2026-10-01: 正しい】確認期間: R5〜R9（5年間）／次期: 確認できず（次期計画の策定業務・アンケートは見当たらず。ただしJR津軽線蟹田以北について、代行バス・わんタク・町営バス等を統合した自動車交通を令和9年4月1日から運行予定（広報今別733号 https://www.town.imabetsu／根拠: https://www.town.imabetsu.lg.jp/gyousei/koukai/2023-0828-1639-1.html 【追加調査 2026-10】環境：町サイト限定検索（town.imabetsu.lg.jp）で『環境基本計画』『地球温暖化対策実行計画』とも該当なし。町の施策一覧 https://www.town.imabetsu.lg.jp/gyousei/shisaku/ には総合計画（第6次、R7〜R16 https://www.town.imabetsu.lg.jp/gyousei/shisaku/files/No.6_sougou.pdf ）・総合戦略・地域公共交通計画等のみで、脱炭素は総合計画内で言及。計画なしの可能性大だが明示根拠に乏しく未確認のまま。確認日2026-10-02。 | S15: 交通のみ調査 | T15: 掲載 | U15: →メモ
A16: 13 | B16: 蓬田村 | C16: =IF(OR(D16="◎",E16="◎"),"◎ 営業",IF(OR(D16="△",E16="△"),"△ 着手済・要確認",IF(OR(D16="？",E16="？"),"？ 期間要確認","✕ 対象外"))) | D16: =IF(J16="計画なし","－",IF(J16="策定済","✕",IF(H16="","？",IF(AND(H16>=TGT_MIN,H16<=TGT_MAX),IF(J16="着手済","△","◎"),"✕")))) | E16: =IF(P16="計画なし","－",IF(P16="策定済","✕",IF(N16="","？",IF(AND(N16>=TGT_MIN,N16<=TGT_MAX),IF(P16="着手済","△","◎"),"✕")))) | G16: 不明 | I16: 不明 | J16: 未確認 | M16: 不明 | O16: 不明 | P16: 未確認 | R16: 交通：村名検索・村HP内検索で地域公共交通計画は見当たらず（公共交通ページ https://www.vill.yomogita.lg.jp/kurashi/kotsu/ のみ）。青森市計画は市単独。なお青森県地域公共交通計画（R5〜R9、県全域）は県計画として全市町村を対象。環境基本計画は町/村名検索・公式サイト内検索で見当たらず（計画なしの確証はないため未確認）。 【追加調査 2026-10】環境：村サイト限定検索（vill.yomogita.lg.jp）で環境基本計画は見当たらず。計画ページ https://www.vill.yomogita.lg.jp/sonsei/keikaku/ には過疎計画（R3〜R7）・青森圏域国土強靱化地域計画等。検索要約で『蓬田村地球温暖化対策推進実行計画』の存在が示唆されたがURL未確認。計画なしの確証はなく未確認のまま。確認日2026-10-02。 | S16: 未調査 | T16: 未掲載
A17: 14 | B17: 外ヶ浜町 | C17: =IF(OR(D17="◎",E17="◎"),"◎ 営業",IF(OR(D17="△",E17="△"),"△ 着手済・要確認",IF(OR(D17="？",E17="？"),"？ 期間要確認","✕ 対象外"))) | D17: =IF(J17="計画なし","－",IF(J17="策定済","✕",IF(H17="","？",IF(AND(H17>=TGT_MIN,H17<=TGT_MAX),IF(J17="着手済","△","◎"),"✕")))) | E17: =IF(P17="計画なし","－",IF(P17="策定済","✕",IF(N17="","？",IF(AND(N17>=TGT_MIN,N17<=TGT_MAX),IF(P17="着手済","△","◎"),"✕")))) | F17: 外ヶ浜町地域公共交通計画 | G17: R6〜R10 | H17: 10 | I17: 推定 | J17: 未確認 | K17: https://www.town.sotogahama.lg.jp/gyosei/public/2024-0227-tiikikoukyokoutukeikaku_pabukome.html | M17: 不明 | O17: 不明 | P17: 計画なし | R17: 交通計画は2024年2月27日パブコメ実施（URLは同パブコメページ、期間は5年と推定）。JR津軽線蟹田〜三厩の代行・転換が絡む。環境基本計画は確認できず（今回検索でも見当たらず）、代替として地球温暖化対策実行計画（区域施策編）令和8年3月策定: https://www.town.sotogahama.lg.jp/gyosei/keikaku/files/01_soto_kuikisesaku_plan.pdf 環境基本計画は検索で確認できず（計画なしの確証なし）。 【追加調査 2026-10】環境：町サイト限定検索で環境基本計画は見当たらず。各種計画ページ https://www.town.sotogahama.lg.jp/gyosei/keikaku/ の環境系は外ヶ浜町地球温暖化対策実行計画（区域施策編、2026-03-24策定）https://www.town.sotogahama.lg.jp/gyosei/keikaku/files/01_soto_kuikisesaku_plan.pdf と事務事業編（2020.3）https://www.town.sotogahama.lg.jp/kurashi/kankyo/2021-1022-ontaiho.html 、一般廃棄物処理基本計画のみ。2023.9ゼロカーボンシティ宣言。区域施策編のみで環境基本計画なしと判断。確認日2026-10-02。 | S17: 調査済 | T17: 掲載
A18: 15 | B18: 鰺ヶ沢町 | C18: =IF(OR(D18="◎",E18="◎"),"◎ 営業",IF(OR(D18="△",E18="△"),"△ 着手済・要確認",IF(OR(D18="？",E18="？"),"？ 期間要確認","✕ 対象外"))) | D18: =IF(J18="計画なし","－",IF(J18="策定済","✕",IF(H18="","？",IF(AND(H18>=TGT_MIN,H18<=TGT_MAX),IF(J18="着手済","△","◎"),"✕")))) | E18: =IF(P18="計画なし","－",IF(P18="策定済","✕",IF(N18="","？",IF(AND(N18>=TGT_MIN,N18<=TGT_MAX),IF(P18="着手済","△","◎"),"✕")))) | F18: 鰺ヶ沢町地域公共交通計画 | G18: R6〜R10 | H18: 10 | I18: 推定 | J18: 未確認 | K18: http://www.town.ajigasawa.lg.jp/gyosei_jyoho/kotsu/kokyokotukeikaku.html | M18: 不明 | O18: 不明 | P18: 計画なし | R18: 交通：旧メモ「単独計画は確認できず」は誤り。町HPで2024年3月策定を確認（パブコメ http://www.town.ajigasawa.lg.jp/gyosei_jyoho/publiccomment/kokyokotukeikaku.html）。期間は未確認で5年と仮定しR6〜R10推定。五所川原圏域定住自立圏構成町。環境基本計画は町/村名検索・公式サイト内検索で見当たらず（計画なしの確証はないため未確認）。 【追加調査 2026-10】環境：『鰺ヶ沢町 環境基本計画』検索・町サイト限定検索（環境基本計画/環境計画/環境基本条例）とも環境基本計画は見当たらず。環境分野は西つがる3市町（五所川原市・鰺ヶ沢町・深浦町）共同の地球温暖化対策実行計画（区域施策編） http://www.town.ajigasawa.lg.jp/gyosei_jyoho/keikaku/kikakusinkou240516.html と再生可能エネルギー導入計画 https://www.town.ajigasawa.lg.jp/gyosei_jyoho/keikaku/seisakusaiene.html のみ（区域施策編のみ）。町計画一覧 https://www.town.ajigasawa.lg.jp/gyosei_jyoho/keikaku/index.html はWebFetchブロックで目視不可。確認日2026-10-02 | S18: 調査済 | T18: 掲載
A19: 16 | B19: 深浦町 | C19: =IF(OR(D19="◎",E19="◎"),"◎ 営業",IF(OR(D19="△",E19="△"),"△ 着手済・要確認",IF(OR(D19="？",E19="？"),"？ 期間要確認","✕ 対象外"))) | D19: =IF(J19="計画なし","－",IF(J19="策定済","✕",IF(H19="","？",IF(AND(H19>=TGT_MIN,H19<=TGT_MAX),IF(J19="着手済","△","◎"),"✕")))) | E19: =IF(P19="計画なし","－",IF(P19="策定済","✕",IF(N19="","？",IF(AND(N19>=TGT_MIN,N19<=TGT_MAX),IF(P19="着手済","△","◎"),"✕")))) | F19: 深浦町地域公共交通計画 | G19: R6〜R10 | H19: 10 | I19: 推定 | J19: 未確認 | K19: https://www.town.fukaura.lg.jp/doc/2020031800019/file_contents/2020031800019_fixed_docs_2020031800019_file_contents_kotsukeikaku.pdf | M19: 不明 | O19: 不明 | P19: 計画なし | R19: 交通：計画書表紙「令和6年4月」。前計画は深浦町地域公共交通網形成計画（2020年3月策定）。期間は未確認で5年と仮定しR6〜R10推定。環境基本計画は町/村名検索・公式サイト内検索で見当たらず（計画なしの確証はないため未確認）。 【追加調査 2026-10】環境：町名検索・町サイト限定検索で環境基本計画は見当たらず。環境系は西つがる3市町地球温暖化対策実行計画［区域施策編］ https://www.town.fukaura.lg.jp/fixed_docs/2024032100017/ 、西つがる3市町再エネ導入計画 https://www.town.fukaura.lg.jp/fixed_docs/2024052000038/ 、循環型社会形成推進地域計画のみ（区域施策編のみ）。確認日2026-10-02 | S19: 調査済 | T19: 掲載
A20: 17 | B20: 西目屋村 | C20: =IF(OR(D20="◎",E20="◎"),"◎ 営業",IF(OR(D20="△",E20="△"),"△ 着手済・要確認",IF(OR(D20="？",E20="？"),"？ 期間要確認","✕ 対象外"))) | D20: =IF(J20="計画なし","－",IF(J20="策定済","✕",IF(H20="","？",IF(AND(H20>=TGT_MIN,H20<=TGT_MAX),IF(J20="着手済","△","◎"),"✕")))) | E20: =IF(P20="計画なし","－",IF(P20="策定済","✕",IF(N20="","？",IF(AND(N20>=TGT_MIN,N20<=TGT_MAX),IF(P20="着手済","△","◎"),"✕")))) | G20: 不明 | I20: 不明 | J20: 未確認 | M20: 不明 | O20: 不明 | P20: 計画なし | R20: 交通：村HP内検索で地域公共交通計画は見当たらず（コミュニティバスのみ https://www.nishimeya.jp/kurashi_tetsuzuki/kokyokotsu/300.html）。弘前市地域公共交通計画（R6.3）は市単独とみられる。なお青森県地域公共交通計画（R5〜R9、県全域）は県計画として全市町村を対象。環境：村HP内検索で環境基本計画は見当たらず（再生可能エネルギー振興策 https://www.nishimeya.jp/sonseijoho/seisaku_keikaku/5/7/228.html、災害廃棄物処理計画R8.1はあり）。計画なしの可能性が高いが確証なく未確認。 【追加調査 2026-10】環境：村名検索・村サイト限定検索で環境基本計画は見当たらず。西目屋村地球温暖化対策実行計画（区域施策編、2024年3月策定） https://www.nishimeya.jp/sonseijoho/gyozaisei/872.html 、バイオマス活用推進計画、再エネ振興策のみ（区域施策編のみ）。確認日2026-10-02 | S20: 環境のみ調査 | T20: 未掲載
A21: 18 | B21: 藤崎町 | C21: =IF(OR(D21="◎",E21="◎"),"◎ 営業",IF(OR(D21="△",E21="△"),"△ 着手済・要確認",IF(OR(D21="？",E21="？"),"？ 期間要確認","✕ 対象外"))) | D21: =IF(J21="計画なし","－",IF(J21="策定済","✕",IF(H21="","？",IF(AND(H21>=TGT_MIN,H21<=TGT_MAX),IF(J21="着手済","△","◎"),"✕")))) | E21: =IF(P21="計画なし","－",IF(P21="策定済","✕",IF(N21="","？",IF(AND(N21>=TGT_MIN,N21<=TGT_MAX),IF(P21="着手済","△","◎"),"✕")))) | G21: 不明 | I21: 不明 | J21: 未確認 | M21: 不明 | O21: 不明 | P21: 計画なし | R21: 交通：町名検索・町HP内検索で地域公共交通計画は見当たらず（都市計画マスタープラン・総合計画のみ）。弘前圏域8市町村の弘南鉄道維持活性化基本方針（2020）あり。なお青森県地域公共交通計画（R5〜R9、県全域）は県計画として全市町村を対象。環境基本計画は町/村名検索・公式サイト内検索で見当たらず（計画なしの確証はないため未確認）。 【追加調査 2026-10】環境：町名検索・町サイト限定検索で環境基本計画は見当たらず。藤崎町地球温暖化対策実行計画（R7策定、計画期間R8〜R12、2030年度52%削減・検索要約による） https://www.town.fujisaki.lg.jp/index.cfm/7,23198,24,339,html のみ（区域施策編のみ）。確認日2026-10-02 | S21: 環境のみ調査 | T21: 未掲載
A22: 19 | B22: 大鰐町 | C22: =IF(OR(D22="◎",E22="◎"),"◎ 営業",IF(OR(D22="△",E22="△"),"△ 着手済・要確認",IF(OR(D22="？",E22="？"),"？ 期間要確認","✕ 対象外"))) | D22: =IF(J22="計画なし","－",IF(J22="策定済","✕",IF(H22="","？",IF(AND(H22>=TGT_MIN,H22<=TGT_MAX),IF(J22="着手済","△","◎"),"✕")))) | E22: =IF(P22="計画なし","－",IF(P22="策定済","✕",IF(N22="","？",IF(AND(N22>=TGT_MIN,N22<=TGT_MAX),IF(P22="着手済","△","◎"),"✕")))) | F22: 大鰐町地域公共交通計画 | G22: R5〜R9 | H22: 9 | I22: 推定 | J22: 未確認 | K22: http://www.town.owani.lg.jp/aboutowani/plan/kokyo-kotsu.html | M22: 不明 | O22: 不明 | P22: 未確認 | R22: 町HP「大鰐町地域公共交通計画策定について」ページに計画PDF（ファイル名R5.5.pdf）掲載→R5.5策定と見られ、5年計画ならR5〜R9（期間は未確認・推定）。過去に計画案策定支援業務の公募型プロポーザル実施: http://www.town.owani.lg.jp/news/index.cfm/detail.1.12187.html （日付未確認）。弘南鉄道大鰐線は運行休止/廃止方向で交通再編の動きあり。環境基本計画・温対計画は検索で見当たらず。 【ファクトチェック 2026-10-01: 確認できず】確認期間: None／次期: 確認できず（関連: 弘南鉄道大鰐線は2028年3月末で運行休止と発表され、代替交通は県主催の検討会議で調整中 https://trafficnews.jp/post/592513）／根拠: http://www.town.owani.lg.jp/aboutowani/plan/kokyo-kotsu.html 【追加調査 2026-10】【2026-10-02調査】検索3回（計画期間・次期計画/プロポ）で、町HP http://www.town.owani.lg.jp/aboutowani/plan/kokyo-kotsu.html のPDF（R5.5.pdf）以外に期間を示す本文は得られず、R5〜R9は推定のまま。町サイトはWebFetch不可（egress blocked）。次期計画の委託・パブコメ等は検索で見当たらず。 【追加調査 2026-10】環境：町名検索・町サイト限定検索（環境基本計画/温対実行計画/環境基本条例）とも該当なし。町計画ページ（振興計画・都市計画MP・地域防災計画等 http://www.town.owani.lg.jp/aboutowani/plan/shinko.html ）に環境計画は出ず。温対区域施策編も未確認のため根拠弱く未確認。確認日2026-10-02 | S22: 交通のみ調査 | T22: 掲載 | U22: →メモ
A23: 20 | B23: 田舎館村 | C23: =IF(OR(D23="◎",E23="◎"),"◎ 営業",IF(OR(D23="△",E23="△"),"△ 着手済・要確認",IF(OR(D23="？",E23="？"),"？ 期間要確認","✕ 対象外"))) | D23: =IF(J23="計画なし","－",IF(J23="策定済","✕",IF(H23="","？",IF(AND(H23>=TGT_MIN,H23<=TGT_MAX),IF(J23="着手済","△","◎"),"✕")))) | E23: =IF(P23="計画なし","－",IF(P23="策定済","✕",IF(N23="","？",IF(AND(N23>=TGT_MIN,N23<=TGT_MAX),IF(P23="着手済","△","◎"),"✕")))) | G23: 不明 | I23: 不明 | J23: 未確認 | M23: 不明 | O23: 不明 | P23: 未確認 | R23: 交通：村HP内検索で地域公共交通計画は見当たらず。弘南鉄道弘南線・大鰐線 維持活性化支援計画（5市町村、2021年1月）に参加 http://www.vill.inakadate.lg.jp/docs/2021022200016/。なお青森県地域公共交通計画（R5〜R9、県全域）は県計画として全市町村を対象。環境基本計画は町/村名検索・公式サイト内検索で見当たらず（計画なしの確証はないため未確認）。 【追加調査 2026-10】環境：村名検索・村サイト限定検索で環境基本計画・温対実行計画・環境基本条例いずれも該当なし（公共施設等総合管理計画等のみ http://www.vill.inakadate.lg.jp/docs/2016102100010/files/sougoukannri-kaitei.pdf ）。計画なしの可能性高いが確証なく未確認。確認日2026-10-02 | S23: 未調査 | T23: 未掲載
A24: 21 | B24: 板柳町 | C24: =IF(OR(D24="◎",E24="◎"),"◎ 営業",IF(OR(D24="△",E24="△"),"△ 着手済・要確認",IF(OR(D24="？",E24="？"),"？ 期間要確認","✕ 対象外"))) | D24: =IF(J24="計画なし","－",IF(J24="策定済","✕",IF(H24="","？",IF(AND(H24>=TGT_MIN,H24<=TGT_MAX),IF(J24="着手済","△","◎"),"✕")))) | E24: =IF(P24="計画なし","－",IF(P24="策定済","✕",IF(N24="","？",IF(AND(N24>=TGT_MIN,N24<=TGT_MAX),IF(P24="着手済","△","◎"),"✕")))) | G24: 不明 | I24: 不明 | J24: 未確認 | M24: 不明 | O24: 不明 | P24: 未確認 | R24: 交通：町名検索・町HP内検索で地域公共交通計画は見当たらず（都市計画マスタープラン案R7.2に公共交通の記述あり https://www.town.itayanagi.aomori.jp/administration/salary/files/toshimasu.pdf）。なお青森県地域公共交通計画（R5〜R9、県全域）は県計画として全市町村を対象。環境基本計画は町/村名検索・公式サイト内検索で見当たらず（計画なしの確証はないため未確認）。 【追加調査 2026-10】環境：町名検索・町サイト限定検索で環境基本計画・温対実行計画・環境基本条例いずれもヒットなし（地域再生計画の汚水処理関連のみ）。計画なしの可能性高いが確証なく未確認。確認日2026-10-02 | S24: 未調査 | T24: 未掲載
A25: 22 | B25: 鶴田町 | C25: =IF(OR(D25="◎",E25="◎"),"◎ 営業",IF(OR(D25="△",E25="△"),"△ 着手済・要確認",IF(OR(D25="？",E25="？"),"？ 期間要確認","✕ 対象外"))) | D25: =IF(J25="計画なし","－",IF(J25="策定済","✕",IF(H25="","？",IF(AND(H25>=TGT_MIN,H25<=TGT_MAX),IF(J25="着手済","△","◎"),"✕")))) | E25: =IF(P25="計画なし","－",IF(P25="策定済","✕",IF(N25="","？",IF(AND(N25>=TGT_MIN,N25<=TGT_MAX),IF(P25="着手済","△","◎"),"✕")))) | G25: 不明 | I25: 不明 | J25: 未確認 | M25: 不明 | O25: 不明 | P25: 計画なし | R25: 交通：町名検索・町HP内検索で地域公共交通計画は見当たらず（各種計画ページ https://www.town.tsuruta.lg.jp/syoukai/syoukai-kakusyu/index.html に該当表示なし、要目視確認）。なお青森県地域公共交通計画（R5〜R9、県全域）は県計画として全市町村を対象。環境基本計画は町/村名検索・公式サイト内検索で見当たらず（計画なしの確証はないため未確認）。 【追加調査 2026-10】環境：町名検索・町サイト限定検索で環境基本計画は見当たらず。各種計画ページ https://www.town.tsuruta.lg.jp/syoukai/syoukai-kakusyu/index.html には鶴田町地域脱炭素実行計画（温対法21条4項の区域施策編・気候変動適応計画兼ねる、R7〜R12、2025年4月策定） https://www.town.tsuruta.lg.jp/info/document/jikko_keikaku.pdf が掲載（区域施策編のみ）。ページはWebFetchブロックで目視未了。確認日2026-10-02 | S25: 環境のみ調査 | T25: 未掲載
A26: 23 | B26: 中泊町 | C26: =IF(OR(D26="◎",E26="◎"),"◎ 営業",IF(OR(D26="△",E26="△"),"△ 着手済・要確認",IF(OR(D26="？",E26="？"),"？ 期間要確認","✕ 対象外"))) | D26: =IF(J26="計画なし","－",IF(J26="策定済","✕",IF(H26="","？",IF(AND(H26>=TGT_MIN,H26<=TGT_MAX),IF(J26="着手済","△","◎"),"✕")))) | E26: =IF(P26="計画なし","－",IF(P26="策定済","✕",IF(N26="","？",IF(AND(N26>=TGT_MIN,N26<=TGT_MAX),IF(P26="着手済","△","◎"),"✕")))) | F26: 中泊町地域公共交通計画 | G26: R5〜R9 | H26: 9 | I26: 確認済 | J26: 未確認 | K26: https://www.town.nakadomari.lg.jp/material/files/group/3/koutuukeikakur6.pdf | M26: 不明 | O26: 不明 | P26: 計画なし | R26: 交通：計画書表紙「令和5年4月」、計画ページ https://www.town.nakadomari.lg.jp/soshikikarasagasu/sogosenryakuka/gyomuannai/5/1/1/4311.html 。ファイル名にr6とあり令和6年に改訂の可能性。期間は未確認で5年と仮定しR5〜R9推定。環境基本計画は町/村名検索・公式サイト内検索で見当たらず（計画なしの確証はないため未確認）。 【ファクトチェック 2026-10-01: 正しい】確認期間: R5〜R9／次期: 確認できず（町のプロポーザル一覧に交通計画関連は見当たらず）／根拠: https://www.town.nakadomari.lg.jp/soshikikarasagasu/sogosenryakuka/gyomuannai/5/1/1/4311.html 【追加調査 2026-10】環境：町名検索・町サイト限定検索で環境基本計画は見当たらず。中泊町地球温暖化対策実行計画（事務事業編・区域施策編）、再エネ導入戦略、NAKAZERO共創アクション（脱炭素行動計画、R8.4策定、脱炭素先行地域選定） https://www.town.nakadomari.lg.jp/soshikikarasagasu/sogosenryakuka/gyomuannai/tikyuuondankataisaku/5369.html のみ（区域施策編のみ）。確認日2026-10-02 | S26: 調査済 | T26: 掲載 | U26: →メモ
A27: 24 | B27: 野辺地町 | C27: =IF(OR(D27="◎",E27="◎"),"◎ 営業",IF(OR(D27="△",E27="△"),"△ 着手済・要確認",IF(OR(D27="？",E27="？"),"？ 期間要確認","✕ 対象外"))) | D27: =IF(J27="計画なし","－",IF(J27="策定済","✕",IF(H27="","？",IF(AND(H27>=TGT_MIN,H27<=TGT_MAX),IF(J27="着手済","△","◎"),"✕")))) | E27: =IF(P27="計画なし","－",IF(P27="策定済","✕",IF(N27="","？",IF(AND(N27>=TGT_MIN,N27<=TGT_MAX),IF(P27="着手済","△","◎"),"✕")))) | G27: 不明 | I27: 不明 | J27: 未確認 | M27: 不明 | O27: 不明 | P27: 未確認 | R27: 交通・環境とも町単独計画は検索で確認できず（町HP「まちの計画」 https://www.town.noheji.aomori.jp/life/chosei/machidukuri/machi-keikaku は存在するが内容未確認、町サイトは取得不可）。地域間幹線系統確保維持費補助金交付要綱あり https://www.town.noheji.aomori.jp/reiki_int/reiki_honbun/c041RG00000724.html 。改定作業の情報なし。 【追加調査 2026-10】環境：町名検索・町サイト限定検索で環境基本計画・温対実行計画・環境基本条例いずれも見当たらず（ヒットは地域防災計画・過疎計画R3〜R7等。過疎計画内に温暖化対策の記述あり https://www.town.noheji.aomori.jp/application/files/8816/4030/5415/ebdf28da23a799a96da8885110e20596.pdf ）。町サイトWebFetch不可。確証なく未確認。確認日2026-10-02 | S27: 未調査 | T27: 未掲載
A28: 25 | B28: 七戸町 | C28: =IF(OR(D28="◎",E28="◎"),"◎ 営業",IF(OR(D28="△",E28="△"),"△ 着手済・要確認",IF(OR(D28="？",E28="？"),"？ 期間要確認","✕ 対象外"))) | D28: =IF(J28="計画なし","－",IF(J28="策定済","✕",IF(H28="","？",IF(AND(H28>=TGT_MIN,H28<=TGT_MAX),IF(J28="着手済","△","◎"),"✕")))) | E28: =IF(P28="計画なし","－",IF(P28="策定済","✕",IF(N28="","？",IF(AND(N28>=TGT_MIN,N28<=TGT_MAX),IF(P28="着手済","△","◎"),"✕")))) | F28: 七戸町地域公共交通網形成計画 | G28: 不明 | I28: 不明 | J28: 未確認 | K28: https://www.town.shichinohe.lg.jp/gyosei/keikaku/kurashi/post-197.html | M28: 不明 | O28: 不明 | P28: 計画なし | R28: 網形成計画（策定支援プロポ: http://www.town.shichinohe.lg.jp/jigyo/nyuusatsu/post-65.html）。期間未確認で既に期限切れの可能性、後継の地域公共交通計画は未確認（H21に地域公共交通会議設置・総合連携計画策定の経緯あり）。環境基本計画は確認できず、関連として地域省エネルギー重点ビジョン（H22）あり（計画なしは弱い根拠）。 環境基本計画は検索で確認できず（計画なしの確証なし）。 【追加調査 2026-10】環境：町名検索・町サイト限定検索・条例検索で環境基本計画/環境基本条例は見当たらず。七戸町地球温暖化対策実行計画（区域施策編、令和6年3月） https://www.town.shichinohe.lg.jp/gyosei/2024/d97c0d43297ff492dc72aae03439179b.pdf が町政情報に掲載（区域施策編のみ）。他に地域省エネルギー重点ビジョン（H22）。確認日2026-10-02 | S28: 調査済 | T28: 掲載／期間満了
A29: 26 | B29: 六戸町 | C29: =IF(OR(D29="◎",E29="◎"),"◎ 営業",IF(OR(D29="△",E29="△"),"△ 着手済・要確認",IF(OR(D29="？",E29="？"),"？ 期間要確認","✕ 対象外"))) | D29: =IF(J29="計画なし","－",IF(J29="策定済","✕",IF(H29="","？",IF(AND(H29>=TGT_MIN,H29<=TGT_MAX),IF(J29="着手済","△","◎"),"✕")))) | E29: =IF(P29="計画なし","－",IF(P29="策定済","✕",IF(N29="","？",IF(AND(N29>=TGT_MIN,N29<=TGT_MAX),IF(P29="着手済","△","◎"),"✕")))) | G29: 不明 | I29: 不明 | J29: 着手済 | M29: 不明 | O29: 不明 | P29: 未確認 | R29: 交通計画は未確認だが、2026年8月31日に「交通まちづくりワークショップ」開催告知（町バス利用者・学生・保護者・事業者対象）: https://www.town.rokunohe.aomori.jp/docs/2026083100015 。地域公共交通計画策定に向けた作業と推定（計画名・プロポは未確認）。環境基本計画・温対計画は検索で見当たらず。 【追加調査 2026-10】環境：町名検索・町サイト限定検索で環境基本計画・温対実行計画・環境基本条例いずれも見当たらず（公共施設等総合管理計画H29等のみ https://www.town.rokunohe.aomori.jp/file/chousei/shisaku/kokyoshisetsusougoukanriplan/kokyoshisetsusougoukanriplan.pdf ）。確証なく未確認。確認日2026-10-02 | S29: 未調査 | T29: 未掲載
A30: 27 | B30: 横浜町 | C30: =IF(OR(D30="◎",E30="◎"),"◎ 営業",IF(OR(D30="△",E30="△"),"△ 着手済・要確認",IF(OR(D30="？",E30="？"),"？ 期間要確認","✕ 対象外"))) | D30: =IF(J30="計画なし","－",IF(J30="策定済","✕",IF(H30="","？",IF(AND(H30>=TGT_MIN,H30<=TGT_MAX),IF(J30="着手済","△","◎"),"✕")))) | E30: =IF(P30="計画なし","－",IF(P30="策定済","✕",IF(N30="","？",IF(AND(N30>=TGT_MIN,N30<=TGT_MAX),IF(P30="着手済","△","◎"),"✕")))) | G30: 不明 | I30: 不明 | J30: 未確認 | M30: 不明 | O30: 不明 | P30: 未確認 | R30: 町単独の地域公共交通計画は確認できず。下北地域公共交通計画（2025年3月策定、下北地域公共交通総合連携協議会）の対象はむつ市・大間町・東通村・風間浦村・佐井村の5市町村で横浜町は含まれない（むつ市資料 https://www.city.mutsu.lg.jp/government/katsudou/kyoudou/files/04kotsu.pdf で確認）。下北半島都市圏広域立地適正化方針（R5.8）には含まれる。町HPに2026-04-10付PDFあり内容未確認 https://www.town.yokohama.lg.jp/index.cfm/6,9299,c,html/9299/20260410-143501.pdf 。環境基本計画・区域施策編も検索で見当たらず（横浜市との再エネ連携協定はあり）。 【追加調査 2026-10】環境：環境基本計画は町名検索・町サイト(town.yokohama.lg.jp)限定検索ともヒットせず。町サイトではゼロカーボンシティ宣言ページに地球温暖化対策実行計画（事務事業編、R6.3策定）と、今後区域施策編を策定予定との記載のみ https://www.town.yokohama.lg.jp/index.cfm/6,11904,18,194,html 。環境基本計画の有無は断定できず未確認のまま。（確認日2026-10-02） | S30: 未調査 | T30: 未掲載
A31: 28 | B31: 東北町 | C31: =IF(OR(D31="◎",E31="◎"),"◎ 営業",IF(OR(D31="△",E31="△"),"△ 着手済・要確認",IF(OR(D31="？",E31="？"),"？ 期間要確認","✕ 対象外"))) | D31: =IF(J31="計画なし","－",IF(J31="策定済","✕",IF(H31="","？",IF(AND(H31>=TGT_MIN,H31<=TGT_MAX),IF(J31="着手済","△","◎"),"✕")))) | E31: =IF(P31="計画なし","－",IF(P31="策定済","✕",IF(N31="","？",IF(AND(N31>=TGT_MIN,N31<=TGT_MAX),IF(P31="着手済","△","◎"),"✕")))) | G31: 不明 | I31: 不明 | J31: 未確認 | M31: 不明 | O31: 不明 | P31: 計画なし | R31: 東北町地域公共交通会議あり（会議録 https://www.town.tohoku.lg.jp/chousei/info/info_yakuba_03-54.html ）。地域公共交通計画の有無は検索で確認できず（東北運輸局の計画一覧PDF https://wwwtb.mlit.go.jp/tohoku/content/000338501.pdf がヒットしたが中身未確認）。環境基本計画も見当たらず、関連は「小川原湖環境再生」計画（地域再生計画、汚水処理）程度。第2期まち・ひと・しごと創生推進計画はR8.4〜R13.3。 【追加調査 2026-10】環境：町サイト限定検索で環境基本計画はヒットせず、代わりに東北町地球温暖化対策実行計画（区域施策編）（計画期間2026〜2035＝R8〜R17、2030年度50%削減・2050実質ゼロ）の策定業務プロポーザル資料・計画ページのみ（区域施策編で対応）。 https://www.town.tohoku.lg.jp/chousei/info/info_yakuba_09-42.html 、仕様書 https://www.town.tohoku.lg.jp/chousei/info/file/info_yakuba_09-29-02.pdf 。根拠は検索結果ベースでやや弱い。（確認日2026-10-02） 根拠: 計画期間は、2026（令和8）年度から2035（令和17）年度までの10年間（区域施策編・検索要約） | S31: 環境のみ調査 | T31: 未掲載
A32: 29 | B32: 六ヶ所村 | C32: =IF(OR(D32="◎",E32="◎"),"◎ 営業",IF(OR(D32="△",E32="△"),"△ 着手済・要確認",IF(OR(D32="？",E32="？"),"？ 期間要確認","✕ 対象外"))) | D32: =IF(J32="計画なし","－",IF(J32="策定済","✕",IF(H32="","？",IF(AND(H32>=TGT_MIN,H32<=TGT_MAX),IF(J32="着手済","△","◎"),"✕")))) | E32: =IF(P32="計画なし","－",IF(P32="策定済","✕",IF(N32="","？",IF(AND(N32>=TGT_MIN,N32<=TGT_MAX),IF(P32="着手済","△","◎"),"✕")))) | F32: 六ヶ所村地域公共交通計画 | G32: R7〜（終期不明） | I32: 不明 | J32: 策定済 | K32: https://www.rokkasho.jp/index.cfm/14,19918,c,html/19918/20250620-120455.pdf | M32: 不明 | O32: 不明 | P32: 計画なし | R32: R7.3策定（素案住民意見聴取後）。計画ページ https://www.rokkasho.jp/index.cfm/11,19571,31,177,html 。R7.6に計画に基づく再編・見直し検討及び実証運行支援業務の公募型プロポーザル実施 https://www.rokkasho.jp/index.cfm/14,19918,31,177,html 。環境基本計画は検索で見当たらず（関連: 水環境保全計画、地域新エネルギービジョン、バイオマスタウン構想）。 【追加調査 2026-10】環境：村サイト限定検索で環境基本計画はヒットせず。代わりに六ヶ所村地球温暖化対策実行計画（区域施策編）（R6.3策定、R6〜R15、ゼロカーボンシティ宣言R4.12）http://www.rokkasho.jp/index.cfm/10,17954,31,124,html 、新エネルギー推進計画、水環境保全計画あり。区域施策編等の個別計画で対応と判断（根拠は検索結果ベース）。（確認日2026-10-02） 根拠: 区域施策編の計画期間 令和6年度～令和15年度（検索要約） | S32: 調査済 | T32: 掲載
A33: 30 | B33: おいらせ町 | C33: =IF(OR(D33="◎",E33="◎"),"◎ 営業",IF(OR(D33="△",E33="△"),"△ 着手済・要確認",IF(OR(D33="？",E33="？"),"？ 期間要確認","✕ 対象外"))) | D33: =IF(J33="計画なし","－",IF(J33="策定済","✕",IF(H33="","？",IF(AND(H33>=TGT_MIN,H33<=TGT_MAX),IF(J33="着手済","△","◎"),"✕")))) | E33: =IF(P33="計画なし","－",IF(P33="策定済","✕",IF(N33="","？",IF(AND(N33>=TGT_MIN,N33<=TGT_MAX),IF(P33="着手済","△","◎"),"✕")))) | F33: 八戸圏域地域公共交通計画（八戸圏域8市町村共同） | G33: R5〜R10 | H33: 10 | I33: 確認済 | J33: 未確認 | K33: https://wwwtb.mlit.go.jp/tohoku/content/000181287.pdf | M33: 不明 | O33: 不明 | P33: 未確認 | R33: 交通計画は八戸圏域8市町村の圏域共同計画（R5〜R10）。環境基本計画は町名検索・ゼロカーボン検索とも該当なし（地域再生計画等のみヒット）。区域施策編も未確認。 【追加調査 2026-10】環境：町名検索・町サイト限定検索とも環境基本計画はヒットせず。町サイトでは第2次総合計画後期基本計画（R6〜R10）https://www.town.oirase.aomori.jp/uploaded/attachment/22191.pdf の環境保全施策、都市計画MP、地球温暖化対策実行計画（事務事業編）、自然・地域と再生可能エネルギー共生審議会 https://www.town.oirase.aomori.jp/soshiki/1232/kanykoukyousei.html のみ。区域施策編も確認できず。（確認日2026-10-02） | S33: 交通のみ調査 | T33: 掲載（広域：八戸圏域）
A34: 31 | B34: 大間町 | C34: =IF(OR(D34="◎",E34="◎"),"◎ 営業",IF(OR(D34="△",E34="△"),"△ 着手済・要確認",IF(OR(D34="？",E34="？"),"？ 期間要確認","✕ 対象外"))) | D34: =IF(J34="計画なし","－",IF(J34="策定済","✕",IF(H34="","？",IF(AND(H34>=TGT_MIN,H34<=TGT_MAX),IF(J34="着手済","△","◎"),"✕")))) | E34: =IF(P34="計画なし","－",IF(P34="策定済","✕",IF(N34="","？",IF(AND(N34>=TGT_MIN,N34<=TGT_MAX),IF(P34="着手済","△","◎"),"✕")))) | F34: 下北地域公共交通計画（下北地域公共交通総合連携協議会：むつ市・大間町・東通村・風間浦村・佐井村） | G34: R7〜R11 | H34: 11 | I34: 確認済 | J34: 策定済 | K34: https://www.city.mutsu.lg.jp/government/katsudou/kyoudou/files/simokitatiikikoukyoukoutuukeikakusoann.pdf | M34: 不明 | O34: 不明 | P34: 未確認 | R34: 交通計画は下北5市町村の圏域共同計画（2025〜2029＝R7〜R11、R7.3策定）。t_urlはむつ市サイト掲載の素案PDF（確定版URLは検索で見つからず）。環境基本計画・温暖化対策実行計画とも検索でヒットせず。 【追加調査 2026-10】環境：環境基本計画は検索でヒットせず。町サイト(town.ooma.lg.jp)の公表情報一覧に第3次地球温暖化対策実行計画（2024-12-13公表、事務事業編とみられる）、第2次(2019)、第1次(2013)の記載あり https://www.town.ooma.lg.jp/allpub_index.html 。環境基本計画の有無は断定できず。（確認日2026-10-02） | S34: 交通のみ調査 | T34: 掲載（広域：下北地域）
A35: 32 | B35: 東通村 | C35: =IF(OR(D35="◎",E35="◎"),"◎ 営業",IF(OR(D35="△",E35="△"),"△ 着手済・要確認",IF(OR(D35="？",E35="？"),"？ 期間要確認","✕ 対象外"))) | D35: =IF(J35="計画なし","－",IF(J35="策定済","✕",IF(H35="","？",IF(AND(H35>=TGT_MIN,H35<=TGT_MAX),IF(J35="着手済","△","◎"),"✕")))) | E35: =IF(P35="計画なし","－",IF(P35="策定済","✕",IF(N35="","？",IF(AND(N35>=TGT_MIN,N35<=TGT_MAX),IF(P35="着手済","△","◎"),"✕")))) | F35: 下北地域公共交通計画（下北地域公共交通総合連携協議会：むつ市・大間町・東通村・風間浦村・佐井村） | G35: R7〜R11 | H35: 11 | I35: 確認済 | J35: 策定済 | K35: https://www.city.mutsu.lg.jp/government/katsudou/kyoudou/files/simokitatiikikoukyoukoutuukeikakusoann.pdf | M35: 不明 | O35: 不明 | P35: 未確認 | R35: 交通計画は下北5市町村の圏域共同計画（2025〜2029＝R7〜R11、R7.3策定）。t_urlはむつ市サイト掲載の素案PDF（確定版URLは検索で見つからず）。環境基本計画は検索でヒットせず（原発モニタリング・風力アセス関連のみ）。 【追加調査 2026-10】環境：環境基本計画は検索でヒットせず（原発関連の環境放射線モニタリング基本計画のみ：県 https://www.pref.aomori.lg.jp/soshiki/kikikanri/atom/higashidori-monitoring-keikaku-R0803.pdf ）。村サイト限定検索は結果なし。温暖化対策実行計画も確認できず。（確認日2026-10-02） | S35: 交通のみ調査 | T35: 掲載（広域：下北地域）
A36: 33 | B36: 風間浦村 | C36: =IF(OR(D36="◎",E36="◎"),"◎ 営業",IF(OR(D36="△",E36="△"),"△ 着手済・要確認",IF(OR(D36="？",E36="？"),"？ 期間要確認","✕ 対象外"))) | D36: =IF(J36="計画なし","－",IF(J36="策定済","✕",IF(H36="","？",IF(AND(H36>=TGT_MIN,H36<=TGT_MAX),IF(J36="着手済","△","◎"),"✕")))) | E36: =IF(P36="計画なし","－",IF(P36="策定済","✕",IF(N36="","？",IF(AND(N36>=TGT_MIN,N36<=TGT_MAX),IF(P36="着手済","△","◎"),"✕")))) | F36: 下北地域公共交通計画（下北地域公共交通総合連携協議会：むつ市・大間町・東通村・風間浦村・佐井村） | G36: R7〜R11 | H36: 11 | I36: 確認済 | J36: 策定済 | K36: https://www.city.mutsu.lg.jp/government/katsudou/kyoudou/files/simokitatiikikoukyoukoutuukeikakusoann.pdf | M36: 不明 | O36: 不明 | P36: 未確認 | R36: 交通計画は下北5市町村の圏域共同計画（2025〜2029＝R7〜R11、R7.3策定）。t_urlはむつ市サイト掲載の素案PDF（確定版URLは検索で見つからず）。環境基本計画・温暖化対策実行計画とも検索でヒットせず。 【追加調査 2026-10】環境：環境基本計画は検索でヒットせず。村サイト(kazamaura.jp)では第2次風間浦村地球温暖化対策実行計画（事務事業編）の2024年度実施状況 https://www.kazamaura.jp/2026/01/27/%E7%AC%AC%EF%BC%92%E6%AC%A1%E9%A2%A8%E9%96%93%E6%B5%A6%E6%9D%91%E5%9C%B0%E7%90%83%E6%B8%A9%E6%9A%96%E5%8C%96%E5%AF%BE%E7%AD%96%E5%AE%9F%E8%A1%8C%E8%A8%88%E7%94%BB%EF%BC%88%E4%BA%8B%E5%8B%99%E4%BA%8B-4/ 、ゼロカーボンシティ宣言（R5.3.1）、ブルーカーボン調査のみ。（確認日2026-10-02） | S36: 交通のみ調査 | T36: 掲載（広域：下北地域）
A37: 34 | B37: 佐井村 | C37: =IF(OR(D37="◎",E37="◎"),"◎ 営業",IF(OR(D37="△",E37="△"),"△ 着手済・要確認",IF(OR(D37="？",E37="？"),"？ 期間要確認","✕ 対象外"))) | D37: =IF(J37="計画なし","－",IF(J37="策定済","✕",IF(H37="","？",IF(AND(H37>=TGT_MIN,H37<=TGT_MAX),IF(J37="着手済","△","◎"),"✕")))) | E37: =IF(P37="計画なし","－",IF(P37="策定済","✕",IF(N37="","？",IF(AND(N37>=TGT_MIN,N37<=TGT_MAX),IF(P37="着手済","△","◎"),"✕")))) | F37: 下北地域公共交通計画（下北地域公共交通総合連携協議会：むつ市・大間町・東通村・風間浦村・佐井村） | G37: R7〜R11 | H37: 11 | I37: 確認済 | J37: 策定済 | K37: https://www.city.mutsu.lg.jp/government/katsudou/kyoudou/files/simokitatiikikoukyoukoutuukeikakusoann.pdf | M37: 不明 | O37: 不明 | P37: 未確認 | R37: 交通計画は下北5市町村の圏域共同計画（2025〜2029＝R7〜R11、R7.3策定）。t_urlはむつ市サイト掲載の素案PDF（確定版URLは検索で見つからず）。環境基本計画・温暖化対策実行計画とも検索でヒットせず。 【追加調査 2026-10】環境：環境基本計画は検索でヒットせず。村サイト(vill.sai.lg.jp)では脱炭素先行地域（2023.4選定）関連補助金 https://www.vill.sai.lg.jp/status-initiatives/decarbonization/ 、ゼロカーボンシティさい表明、ブルーカーボン推進事業のみ。温暖化対策実行計画の有無も未確認。（確認日2026-10-02） | S37: 交通のみ調査 | T37: 掲載（広域：下北地域）
A38: 35 | B38: 三戸町 | C38: =IF(OR(D38="◎",E38="◎"),"◎ 営業",IF(OR(D38="△",E38="△"),"△ 着手済・要確認",IF(OR(D38="？",E38="？"),"？ 期間要確認","✕ 対象外"))) | D38: =IF(J38="計画なし","－",IF(J38="策定済","✕",IF(H38="","？",IF(AND(H38>=TGT_MIN,H38<=TGT_MAX),IF(J38="着手済","△","◎"),"✕")))) | E38: =IF(P38="計画なし","－",IF(P38="策定済","✕",IF(N38="","？",IF(AND(N38>=TGT_MIN,N38<=TGT_MAX),IF(P38="着手済","△","◎"),"✕")))) | F38: 八戸圏域地域公共交通計画（八戸圏域8市町村共同） | G38: R5〜R10 | H38: 10 | I38: 確認済 | J38: 未確認 | K38: https://wwwtb.mlit.go.jp/tohoku/content/000181287.pdf | M38: 不明 | O38: 不明 | P38: 計画なし | R38: 交通計画は八戸圏域8市町村の圏域共同計画（R5〜R10）。環境基本計画・地球温暖化対策実行計画とも検索でヒットせず（地域再生計画・風力アセスのみ）。 【追加調査 2026-10】環境：町名検索・町サイト限定検索とも環境基本計画はヒットせず。代わりに三戸町地球温暖化対策実行計画（事務事業編＋町全体の区域の削減施策を含む、R6〜R12、2030年度58.7%削減）https://www.town.sannohe.aomori.jp/soshiki/soumu/gyouseijouhou/1/4712.html と2050ゼロカーボン宣言。温暖化実行計画で対応と判断（根拠は検索結果ベース）。（確認日2026-10-02） 根拠: 計画期間 令和6年度～令和12年度（温暖化実行計画・検索要約） | S38: 調査済 | T38: 掲載（広域：八戸圏域）
A39: 36 | B39: 五戸町 | C39: =IF(OR(D39="◎",E39="◎"),"◎ 営業",IF(OR(D39="△",E39="△"),"△ 着手済・要確認",IF(OR(D39="？",E39="？"),"？ 期間要確認","✕ 対象外"))) | D39: =IF(J39="計画なし","－",IF(J39="策定済","✕",IF(H39="","？",IF(AND(H39>=TGT_MIN,H39<=TGT_MAX),IF(J39="着手済","△","◎"),"✕")))) | E39: =IF(P39="計画なし","－",IF(P39="策定済","✕",IF(N39="","？",IF(AND(N39>=TGT_MIN,N39<=TGT_MAX),IF(P39="着手済","△","◎"),"✕")))) | F39: 八戸圏域地域公共交通計画（八戸圏域8市町村共同） | G39: R5〜R10 | H39: 10 | I39: 確認済 | J39: 未確認 | K39: https://wwwtb.mlit.go.jp/tohoku/content/000181287.pdf | M39: 不明 | O39: 不明 | P39: 計画なし | R39: 交通計画は八戸圏域8市町村の圏域共同計画（R5〜R10）。環境基本計画は検索でヒットせず。代替として五戸町地球温暖化対策実行計画（区域施策編・地域気候変動適応計画兼ねる、R7.3策定、環境省地域脱炭素実現支援事業で作成）あり：https://www.town.gonohe.aomori.jp/chosei/tikyuondankahonpen.pdf （概要版 https://www.town.gonohe.aomori.jp/chosei/tikyuondankagaiyouban.pdf ）。期間は検索結果で確認できず。環境省策定状況 https://www.env.go.jp/policy/local_keikaku/sakutei2/02/02442.html 【追加調査 2026-10】環境：町名検索で環境基本計画はヒットせず、町サイトPDFは五戸町地球温暖化対策実行計画（区域施策編・適応計画兼、R7.3策定、計画期間R7〜R12）https://www.town.gonohe.aomori.jp/chosei/tikyuondankahonpen.pdf 、概要版 https://www.town.gonohe.aomori.jp/chosei/tikyuondankagaiyouban.pdf 、ごみ処理基本計画（R8〜R17）のみ。区域施策編のみと判断。（確認日2026-10-02） 根拠: 令和7（2025）年度から令和12（2030）年度までの6年間（区域施策編概要版・検索要約） | S39: 調査済 | T39: 掲載（広域：八戸圏域）
A40: 37 | B40: 田子町 | C40: =IF(OR(D40="◎",E40="◎"),"◎ 営業",IF(OR(D40="△",E40="△"),"△ 着手済・要確認",IF(OR(D40="？",E40="？"),"？ 期間要確認","✕ 対象外"))) | D40: =IF(J40="計画なし","－",IF(J40="策定済","✕",IF(H40="","？",IF(AND(H40>=TGT_MIN,H40<=TGT_MAX),IF(J40="着手済","△","◎"),"✕")))) | E40: =IF(P40="計画なし","－",IF(P40="策定済","✕",IF(N40="","？",IF(AND(N40>=TGT_MIN,N40<=TGT_MAX),IF(P40="着手済","△","◎"),"✕")))) | F40: 八戸圏域地域公共交通計画（八戸圏域8市町村共同） | G40: R5〜R10 | H40: 10 | I40: 確認済 | J40: 未確認 | K40: https://wwwtb.mlit.go.jp/tohoku/content/000181287.pdf | M40: 不明 | O40: 不明 | P40: 未確認 | R40: 交通計画は八戸圏域8市町村の圏域共同計画（R5〜R10）。環境基本計画・温暖化対策実行計画とも検索でヒットせず。 【追加調査 2026-10】環境：環境基本計画は町名検索・町サイト限定検索ともヒットせず。町サイト計画ページには田子町総合計画、地球温暖化対策実行計画（事務事業編、H24〜H28と古い）https://www.town.takko.lg.jp/index.cfm/13,234,50,202,html 、森林整備計画等。計画一覧 http://www.town.takko.lg.jp/index.cfm/13,0,50,202,html の全体は未確認のため未確認のまま。（確認日2026-10-02） | S40: 交通のみ調査 | T40: 掲載（広域：八戸圏域）
...

Sheet 岩手県
A1: 岩手県 地域公共交通計画・環境基本計画の終期一覧（2026年9月30日時点の調査）
A2: ="営業判定の対象：終期 R"&TGT_MIN&"〜R"&TGT_MAX&"年度 →◎（着手済は△、期間不明は？）。終期セルの色：緑＝対象年度／橙＝その翌年度（次の候補）。対象年度は「集計・設定」シートのC4・C5のプルダウンで切替。"
A3: No | B3: 市町村 | C3: 営業判定 | D3: 交通判定 | E3: 環境判定 | F3: 地域公共交通計画 | G3: 交通 計画期間 | H3: 交通 終期(令和年度) | I3: 交通 確度 | J3: 交通 改定状況 | K3: 交通 計画リンク（エビデンス） | L3: 環境基本計画 | M3: 環境 計画期間 | N3: 環境 終期(令和年度) | O3: 環境 確度 | P3: 環境 改定状況 | Q3: 環境 計画リンク（エビデンス） | R3: 注釈（改定作業の状況など） | S3: 調査状況 | T3: 国交省一覧(R8.5末) | U3: 営業メモ | V3: 位置図
A4: 1 | B4: 盛岡市 | C4: =IF(OR(D4="◎",E4="◎"),"◎ 営業",IF(OR(D4="△",E4="△"),"△ 着手済・要確認",IF(OR(D4="？",E4="？"),"？ 期間要確認","✕ 対象外"))) | D4: =IF(J4="計画なし","－",IF(J4="策定済","✕",IF(H4="","？",IF(AND(H4>=TGT_MIN,H4<=TGT_MAX),IF(J4="着手済","△","◎"),"✕")))) | E4: =IF(P4="計画なし","－",IF(P4="策定済","✕",IF(N4="","？",IF(AND(N4>=TGT_MIN,N4<=TGT_MAX),IF(P4="着手済","△","◎"),"✕")))) | F4: 盛岡都市圏地域公共交通計画（盛岡市・滝沢市・矢巾町共同） | G4: R8〜R12 | H4: 12 | I4: 確認済 | J4: 策定済 | K4: https://www.city.morioka.iwate.jp/_res/projects/default_project/_page_/001/043/162/R7honpen.pdf | L4: 盛岡市環境基本計画（第三次） | M4: R3〜R12 | N4: 12 | O4: 確認済 | P4: 未確認 | Q4: https://www.city.morioka.iwate.jp/_res/projects/default_project/_page_/001/010/054/kihonntekizikou.pdf | R4: 交通：3市町共同の都市圏計画をR7.9.30公表（R8〜R12）。環境：R3〜R12の10年計画、改定作業は未確認。 | S4: 調査済 | T4: 掲載（広域：盛岡市・滝沢市・矢巾町）
A5: 2 | B5: 宮古市 | C5: =IF(OR(D5="◎",E5="◎"),"◎ 営業",IF(OR(D5="△",E5="△"),"△ 着手済・要確認",IF(OR(D5="？",E5="？"),"？ 期間要確認","✕ 対象外"))) | D5: =IF(J5="計画なし","－",IF(J5="策定済","✕",IF(H5="","？",IF(AND(H5>=TGT_MIN,H5<=TGT_MAX),IF(J5="着手済","△","◎"),"✕")))) | E5: =IF(P5="計画なし","－",IF(P5="策定済","✕",IF(N5="","？",IF(AND(N5>=TGT_MIN,N5<=TGT_MAX),IF(P5="着手済","△","◎"),"✕")))) | F5: 宮古市地域公共交通計画 | G5: R5〜R11 | H5: 11 | I5: 確認済 | J5: 未確認 | K5: https://www.city.miyako.iwate.jp/material/files/group/8/miyakositiikikoukyoukoutuukeikaku.pdf | L5: 宮古市環境基本計画（R7.3策定） | M5: R7〜R12 | N5: 12 | O5: 確認済 | P5: 策定済 | Q5: https://www.city.miyako.iwate.jp/material/files/group/14/kihonkeikaku.pdf | R5: 交通：2023〜2029年度の7年計画。利便増進実施計画あり https://www.city.miyako.iwate.jp/material/files/group/8/miyakosiribennzousinnjissikeikaku.pdf 。三陸鉄道沿線の広域計画 https://www.city.miyako.iwate.jp/material/files/group/8/sanntetsukoutuukeikaku2024.pdf もあり。環境：前計画R2〜R6、R7.3に新計画策定（R7〜R12）。 三陸鉄道沿線地域等公共交通計画の策定ページ https://www.city.miyako.iwate.jp/gyosei/soshiki/kokyokotsuusuishin/2/1/605.html 。 | S5: 調査済 | T5: 掲載（広域：三陸鉄道沿線地域等）
A6: 3 | B6: 大船渡市 | C6: =IF(OR(D6="◎",E6="◎"),"◎ 営業",IF(OR(D6="△",E6="△"),"△ 着手済・要確認",IF(OR(D6="？",E6="？"),"？ 期間要確認","✕ 対象外"))) | D6: =IF(J6="計画なし","－",IF(J6="策定済","✕",IF(H6="","？",IF(AND(H6>=TGT_MIN,H6<=TGT_MAX),IF(J6="着手済","△","◎"),"✕")))) | E6: =IF(P6="計画なし","－",IF(P6="策定済","✕",IF(N6="","？",IF(AND(N6>=TGT_MIN,N6<=TGT_MAX),IF(P6="着手済","△","◎"),"✕")))) | F6: 大船渡市地域公共交通計画 | G6: R8〜R12 | H6: 12 | I6: 確認済 | J6: 策定済 | K6: https://www.city.ofunato.iwate.jp/archive/contents-5125 | L6: 第3次大船渡市環境基本計画 | M6: R5〜R14 | N6: 14 | O6: 確認済 | P6: 未確認 | Q6: https://www.city.ofunato.iwate.jp/site/kankyokeikaku/ | R6: 交通：旧計画R4〜R7（R6.9第一次改定 https://www.city.ofunato.iwate.jp/uploads/contents/archive_0000000476_00/38921.pdf ）の後継として、計画ページ上の期間はR8〜R12（検索結果本文）。R8.7に持続可能な鉄道接続型地域交通モデル調査業務プロポーザル https://www.city.ofunato.iwate.jp/archive/p20260721171526 。三陸鉄道沿線地域等公共交通計画（岩手県・沿線12市町村の広域計画、2024策定） https://www.city.miyako.iwate.jp/gyosei/soshiki/kokyokotsuusuishin/2/1/605.html もカバー。環境：R5年度から10年間（パブコメR5.1）。 | S6: 調査済 | T6: 掲載（広域：三陸鉄道沿線地域等）
A7: 4 | B7: 花巻市 | C7: =IF(OR(D7="◎",E7="◎"),"◎ 営業",IF(OR(D7="△",E7="△"),"△ 着手済・要確認",IF(OR(D7="？",E7="？"),"？ 期間要確認","✕ 対象外"))) | D7: =IF(J7="計画なし","－",IF(J7="策定済","✕",IF(H7="","？",IF(AND(H7>=TGT_MIN,H7<=TGT_MAX),IF(J7="着手済","△","◎"),"✕")))) | E7: =IF(P7="計画なし","－",IF(P7="策定済","✕",IF(N7="","？",IF(AND(N7>=TGT_MIN,N7<=TGT_MAX),IF(P7="着手済","△","◎"),"✕")))) | F7: 花巻市地域公共交通計画 | G7: R6〜R10 | H7: 10 | I7: 確認済 | J7: 未確認 | K7: https://www.city.hanamaki.iwate.jp/_res/projects/default_project/_page_/001/021/245/keikaku.pdf | L7: 第3次花巻市環境基本計画 | M7: R6〜R13 | N7: 13 | O7: 確認済 | P7: 未確認 | Q7: https://www.city.hanamaki.iwate.jp/shisei/shisei/keikaku/1002782.html | R7: 交通：R6.3策定、R6〜R10の5年。環境：第2次（H28.3〜R6.3満了）の後継としてR6.3に第3次策定（R6〜R13の8年）、区域施策編を別冊で同時策定。 | S7: 調査済 | T7: 掲載
A8: 5 | B8: 北上市 | C8: =IF(OR(D8="◎",E8="◎"),"◎ 営業",IF(OR(D8="△",E8="△"),"△ 着手済・要確認",IF(OR(D8="？",E8="？"),"？ 期間要確認","✕ 対象外"))) | D8: =IF(J8="計画なし","－",IF(J8="策定済","✕",IF(H8="","？",IF(AND(H8>=TGT_MIN,H8<=TGT_MAX),IF(J8="着手済","△","◎"),"✕")))) | E8: =IF(P8="計画なし","－",IF(P8="策定済","✕",IF(N8="","？",IF(AND(N8>=TGT_MIN,N8<=TGT_MAX),IF(P8="着手済","△","◎"),"✕")))) | F8: 北上市地域公共交通計画2026-2030 | G8: R8〜R12 | H8: 12 | I8: 確認済 | J8: 策定済 | K8: https://www.city.kitakami.iwate.jp/life/soshikikarasagasu/toshisaiseisuishin/koutsuuseisaku/1_1/21919.html | L8: 北上市環境基本計画（第三次、R8.3改定） | M8: R3〜R12 | N8: 12 | O8: 確認済 | P8: 未確認 | Q8: https://www.city.kitakami.iwate.jp/material/files/group/14/kankyokeikaku_0803.pdf | R8: 交通：R8〜R12の新計画を策定（案 R8.3.13会議資料 https://www.city.kitakami.iwate.jp/material/files/group/56/260313_siryou.pdf ）。環境：第三次R3〜R12、R8.3中間改定（区域施策編も改定）。 | S8: 調査済 | T8: 掲載
A9: 6 | B9: 久慈市 | C9: =IF(OR(D9="◎",E9="◎"),"◎ 営業",IF(OR(D9="△",E9="△"),"△ 着手済・要確認",IF(OR(D9="？",E9="？"),"？ 期間要確認","✕ 対象外"))) | D9: =IF(J9="計画なし","－",IF(J9="策定済","✕",IF(H9="","？",IF(AND(H9>=TGT_MIN,H9<=TGT_MAX),IF(J9="着手済","△","◎"),"✕")))) | E9: =IF(P9="計画なし","－",IF(P9="策定済","✕",IF(N9="","？",IF(AND(N9>=TGT_MIN,N9<=TGT_MAX),IF(P9="着手済","△","◎"),"✕")))) | F9: 久慈市地域公共交通計画（R6.3策定） | G9: H30〜R9 | H9: 9 | I9: 推定 | J9: 未確認 | K9: https://www.city.kuji.lg.jp/material/files/group/19/keikaku.pdf | L9: 第2次久慈市環境基本計画 | M9: H30〜R9 | N9: 9 | O9: 確認済 | P9: 未確認 | Q9: https://www.city.kuji.lg.jp/material/files/group/19/2021_kuji_kankyou_1.pdf | R9: 交通：網形成計画（H30〜）をR6.3に地域公共交通計画として策定、計画期間は2018〜2027年度（R9終期）とする検索結果が1回のみで、2026.10の再検索では裏付けが得られず推定、2028年度以降に見直し予定。計画ページ https://www.city.kuji.lg.jp/soshiki/chiikizukurishinko/1/6/1/1835.html 。次期計画の委託等は未確認。三陸鉄道沿線地域等公共交通計画（岩手県・沿線12市町村の広域計画、2024策定） https://www.city.miyako.iwate.jp/gyosei/soshiki/kokyokotsuusuishin/2/1/605.html もカバー。環境：10年計画（R10以降に見直しとの記載あり）、正確な期間未確認。区域施策編改訂支援業務プロポーザルあり https://www.city.kuji.iwate.jp/assets/fukushi/siyousyo_ondankapropo.pdf 。 【ファクトチェック 2026-10-01: 確認できず】確認期間: None／次期: 確認できず／根拠: https://www.city.kuji.lg.jp/soshiki/chiikizukurishinko/1/6/1/1835.html 【追加調査 2026-10】【2026-10-02調査】検索3回で計画ページ https://www.city.kuji.lg.jp/soshiki/chiikizukurishinko/1/6/1/1835.html は確認できたが、計画期間（H30〜R9=2018〜2027年度）を示す本文抜粋は得られず推定のまま。市サイトはWebFetch不可（egress blocked）。次期計画の委託等も検索で見当たらず。 【追加調査 2026-10】環境：市サイト限定検索2回で『第1章 計画の基本的事項』(2021_kuji_kankyou_1.pdf)の本文として「2018年度から2027年度までの10年間」を確認（PDF直接取得は不可）。前回メモの『R10以降に見直し』と整合。R9終期のため次期（第3次）計画の策定委託・審議会・パブコメを検索したが見当たらず（着手未確認）。確認日2026-10-02。 根拠: 計画の期間は…2018年度から2027年度までの10年間とします | S9: 調査済 | T9: 掲載（広域：三陸鉄道沿線地域等） | U9: →メモ
A10: 7 | B10: 遠野市 | C10: =IF(OR(D10="◎",E10="◎"),"◎ 営業",IF(OR(D10="△",E10="△"),"△ 着手済・要確認",IF(OR(D10="？",E10="？"),"？ 期間要確認","✕ 対象外"))) | D10: =IF(J10="計画なし","－",IF(J10="策定済","✕",IF(H10="","？",IF(AND(H10>=TGT_MIN,H10<=TGT_MAX),IF(J10="着手済","△","◎"),"✕")))) | E10: =IF(P10="計画なし","－",IF(P10="策定済","✕",IF(N10="","？",IF(AND(N10>=TGT_MIN,N10<=TGT_MAX),IF(P10="着手済","△","◎"),"✕")))) | F10: 遠野市地域公共交通計画 | G10: R7〜R12 | H10: 12 | I10: 確認済 | J10: 策定済 | K10: https://www.city.tono.iwate.jp/index.cfm/50,13281,311,html | L10: 第5次遠野市環境基本計画 | M10: R8〜R12 | N10: 12 | O10: 確認済 | P10: 策定済 | Q10: https://www.city.tono.iwate.jp/index.cfm/45,34797,247,html | R10: 交通：R7〜R12（R7年度開始の新計画）。環境：第5次計画を公開、期間は検索結果で未確認。 【追加調査 2026-10】環境：市サイト限定検索2回（別クエリ）で環境基本計画ページの本文として「第５次遠野市環境基本計画の期間は令和8年から令和12年度まで」を確認。R8開始の新計画（第3次遠野市総合計画R8〜R17と同時期）のため策定済と判断（策定月・パブコメは未確認）。市サイトはWebFetchブロック。確認日2026-10-02。URL https://www.city.tono.iwate.jp/index.cfm/45,34797,247,html 根拠: 第５次遠野市環境基本計画…令和8年から令和12年度まで | S10: 調査済 | T10: 掲載
A11: 8 | B11: 一関市 | C11: =IF(OR(D11="◎",E11="◎"),"◎ 営業",IF(OR(D11="△",E11="△"),"△ 着手済・要確認",IF(OR(D11="？",E11="？"),"？ 期間要確認","✕ 対象外"))) | D11: =IF(J11="計画なし","－",IF(J11="策定済","✕",IF(H11="","？",IF(AND(H11>=TGT_MIN,H11<=TGT_MAX),IF(J11="着手済","△","◎"),"✕")))) | E11: =IF(P11="計画なし","－",IF(P11="策定済","✕",IF(N11="","？",IF(AND(N11>=TGT_MIN,N11<=TGT_MAX),IF(P11="着手済","△","◎"),"✕")))) | F11: 一関市地域公共交通計画 | G11: R6〜R10 | H11: 10 | I11: 確認済 | J11: 未確認 | K11: https://www.city.ichinoseki.iwate.jp/index.cfm/7,166695,c,html/166695/20240410-160623.pdf | L11: 一関市環境基本計画（R3.3改定） | M11: H29〜R8 | N11: 8 | O11: 確認済 | P11: 未確認 | Q11: https://www.city.ichinoseki.iwate.jp/index.cfm/7,90284,125,html | R11: 交通：R6〜R10、一部改訂あり https://www.city.ichinoseki.iwate.jp/index.cfm/7,175828,125,html 。環境：H29〜R8の10年計画でR8年度終期。次期計画の策定作業（委託・パブコメ）は検索で確認できず。要注視。 | S11: 調査済 | T11: 掲載
A12: 9 | B12: 陸前高田市 | C12: =IF(OR(D12="◎",E12="◎"),"◎ 営業",IF(OR(D12="△",E12="△"),"△ 着手済・要確認",IF(OR(D12="？",E12="？"),"？ 期間要確認","✕ 対象外"))) | D12: =IF(J12="計画なし","－",IF(J12="策定済","✕",IF(H12="","？",IF(AND(H12>=TGT_MIN,H12<=TGT_MAX),IF(J12="着手済","△","◎"),"✕")))) | E12: =IF(P12="計画なし","－",IF(P12="策定済","✕",IF(N12="","？",IF(AND(N12>=TGT_MIN,N12<=TGT_MAX),IF(P12="着手済","△","◎"),"✕")))) | F12: 陸前高田市地域公共交通計画 | G12: R6〜R10 | H12: 10 | I12: 確認済 | J12: 未確認 | K12: https://www.city.rikuzentakata.iwate.jp/material/files/group/19/20231124_4-2.pdf | M12: 不明 | O12: 不明 | P12: 計画なし | R12: 交通：2024〜2028年度の5年。計画ページ https://www.city.rikuzentakata.iwate.jp/soshiki/machizukurisuishinka/seikatsukankyokakari/3/8100.html 。環境：環境基本計画は検索で確認できず（まちづくり総合計画・SDGs未来都市計画で代替か）。 | S12: 調査済 | T12: 掲載（広域：三陸鉄道沿線地域等）
A13: 10 | B13: 釜石市 | C13: =IF(OR(D13="◎",E13="◎"),"◎ 営業",IF(OR(D13="△",E13="△"),"△ 着手済・要確認",IF(OR(D13="？",E13="？"),"？ 期間要確認","✕ 対象外"))) | D13: =IF(J13="計画なし","－",IF(J13="策定済","✕",IF(H13="","？",IF(AND(H13>=TGT_MIN,H13<=TGT_MAX),IF(J13="着手済","△","◎"),"✕")))) | E13: =IF(P13="計画なし","－",IF(P13="策定済","✕",IF(N13="","？",IF(AND(N13>=TGT_MIN,N13<=TGT_MAX),IF(P13="着手済","△","◎"),"✕")))) | F13: 釜石市地域公共交通計画（R6.1一部改訂） | G13: R3〜R7 | H13: 7 | I13: 確認済 | J13: 未確認 | K13: https://www.city.kamaishi.iwate.jp/docs/2021040500020/file_contents/001.pdf | L13: 第二次釜石市環境基本計画 | M13: R5〜R12 | N13: 12 | O13: 確認済 | P13: 未確認 | Q13: https://www.city.kamaishi.iwate.jp/docs/2023110200014/ | R13: 交通：R3〜R7で終期経過。R8.2施政方針でも現計画に基づく取組を記載、次期計画の策定・延長は検索で確認できず。環境：2023〜2030の8年、中間見直し予定。 | S13: 調査済 | T13: 掲載（広域：三陸鉄道沿線地域等）
A14: 11 | B14: 二戸市 | C14: =IF(OR(D14="◎",E14="◎"),"◎ 営業",IF(OR(D14="△",E14="△"),"△ 着手済・要確認",IF(OR(D14="？",E14="？"),"？ 期間要確認","✕ 対象外"))) | D14: =IF(J14="計画なし","－",IF(J14="策定済","✕",IF(H14="","？",IF(AND(H14>=TGT_MIN,H14<=TGT_MAX),IF(J14="着手済","△","◎"),"✕")))) | E14: =IF(P14="計画なし","－",IF(P14="策定済","✕",IF(N14="","？",IF(AND(N14>=TGT_MIN,N14<=TGT_MAX),IF(P14="着手済","△","◎"),"✕")))) | F14: 二戸市地域公共交通計画 | G14: 不明 | I14: 不明 | J14: 未確認 | K14: https://www.city.ninohe.lg.jp/info/2661 | M14: 不明 | O14: 不明 | P14: 計画なし | R14: 交通：計画ページ（2021.6.30掲載）あり、期間は検索結果で確認できず（R3策定なら5年でR7終期の可能性）。環境：環境基本計画は検索で確認できず。 | S14: 調査済 | T14: 掲載
A15: 12 | B15: 八幡平市 | C15: =IF(OR(D15="◎",E15="◎"),"◎ 営業",IF(OR(D15="△",E15="△"),"△ 着手済・要確認",IF(OR(D15="？",E15="？"),"？ 期間要確認","✕ 対象外"))) | D15: =IF(J15="計画なし","－",IF(J15="策定済","✕",IF(H15="","？",IF(AND(H15>=TGT_MIN,H15<=TGT_MAX),IF(J15="着手済","△","◎"),"✕")))) | E15: =IF(P15="計画なし","－",IF(P15="策定済","✕",IF(N15="","？",IF(AND(N15>=TGT_MIN,N15<=TGT_MAX),IF(P15="着手済","△","◎"),"✕")))) | F15: 八幡平市地域公共交通計画 | G15: R6〜R12 | H15: 12 | I15: 確認済 | J15: 未確認 | K15: https://www.city.hachimantai.lg.jp/soshiki/machi/1517.html | L15: 第2次八幡平市環境基本計画 | M15: R4〜R13 | N15: 13 | O15: 確認済 | P15: 未確認 | Q15: https://www.city.hachimantai.lg.jp/uploaded/attachment/13185.pdf | R15: 交通：2024年3月策定、R6〜R12の7年。環境：R4.7策定、R4〜R13、区域施策編を内包。e_urlは案段階PDF。 | S15: 調査済 | T15: 掲載
A16: 13 | B16: 奥州市 | C16: =IF(OR(D16="◎",E16="◎"),"◎ 営業",IF(OR(D16="△",E16="△"),"△ 着手済・要確認",IF(OR(D16="？",E16="？"),"？ 期間要確認","✕ 対象外"))) | D16: =IF(J16="計画なし","－",IF(J16="策定済","✕",IF(H16="","？",IF(AND(H16>=TGT_MIN,H16<=TGT_MAX),IF(J16="着手済","△","◎"),"✕")))) | E16: =IF(P16="計画なし","－",IF(P16="策定済","✕",IF(N16="","？",IF(AND(N16>=TGT_MIN,N16<=TGT_MAX),IF(P16="着手済","△","◎"),"✕")))) | F16: 奥州市地域公共交通計画（第4次奥州市バス交通計画） | G16: R6〜R10 | H16: 10 | I16: 確認済 | J16: 未確認 | K16: https://www.city.oshu.iwate.jp/soshiki/2/1004/12523.html | L16: 第2次奥州市環境基本計画（R4.3改定） | M16: H29〜R8 | N16: 8 | O16: 確認済 | P16: 着手済 | Q16: https://www.city.oshu.iwate.jp/material/files/group/183/dai2jikankyoukihonnkeikaku_GX.pdf | R16: 交通：R6.3策定、変更あり https://www.city.oshu.iwate.jp/soshiki/2/1004/17684.html 。R6〜R10（県計画との整合）。県利便増進実施計画（奥州市版）R8.2 https://www.city.oshu.iwate.jp/soshiki/2/1004/17721.html 。環境：R8年度終期。R7年度に基礎調査委託、R8年度素案策定、R9.4から第3次計画（区域施策編含む）開始予定（市議会建設環境常任委員会R6.10.8会議録 https://www.city.oshu.iwate.jp/material/files/group/76/202410080000001.pdf ）。 | S16: 調査済 | T16: 掲載
A17: 14 | B17: 滝沢市 | C17: =IF(OR(D17="◎",E17="◎"),"◎ 営業",IF(OR(D17="△",E17="△"),"△ 着手済・要確認",IF(OR(D17="？",E17="？"),"？ 期間要確認","✕ 対象外"))) | D17: =IF(J17="計画なし","－",IF(J17="策定済","✕",IF(H17="","？",IF(AND(H17>=TGT_MIN,H17<=TGT_MAX),IF(J17="着手済","△","◎"),"✕")))) | E17: =IF(P17="計画なし","－",IF(P17="策定済","✕",IF(N17="","？",IF(AND(N17>=TGT_MIN,N17<=TGT_MAX),IF(P17="着手済","△","◎"),"✕")))) | F17: 盛岡都市圏地域公共交通計画（盛岡市・滝沢市・矢巾町共同） | G17: R8〜R12 | H17: 12 | I17: 確認済 | J17: 策定済 | K17: https://www.city.morioka.iwate.jp/_res/projects/default_project/_page_/001/043/162/R7honpen.pdf | L17: 第1次滝沢市環境基本計画 | M17: R5〜R12 | N17: 12 | O17: 確認済 | P17: 未確認 | Q17: https://www.city.takizawa.iwate.jp/kurashi/kankyo/contents-12768/p20241204162009 | R17: 交通：3市町共同の都市圏計画（R7.9公表）。滝沢市側資料 https://www.city.takizawa.iwate.jp/uploads/contents/pages_0000002369_00/【資料3】次期地域公共交通計画の検討状況及び現行計画の変更等について.pdf 。環境：R5.3策定、R5〜R12の8年。 | S17: 調査済 | T17: 掲載（広域：盛岡市・滝沢市・矢巾町）
A18: 15 | B18: 雫石町 | C18: =IF(OR(D18="◎",E18="◎"),"◎ 営業",IF(OR(D18="△",E18="△"),"△ 着手済・要確認",IF(OR(D18="？",E18="？"),"？ 期間要確認","✕ 対象外"))) | D18: =IF(J18="計画なし","－",IF(J18="策定済","✕",IF(H18="","？",IF(AND(H18>=TGT_MIN,H18<=TGT_MAX),IF(J18="着手済","△","◎"),"✕")))) | E18: =IF(P18="計画なし","－",IF(P18="策定済","✕",IF(N18="","？",IF(AND(N18>=TGT_MIN,N18<=TGT_MAX),IF(P18="着手済","△","◎"),"✕")))) | F18: 第2次雫石町地域公共交通計画 | G18: R7〜R11 | H18: 11 | I18: 確認済 | J18: 策定済 | K18: https://www.town.shizukuishi.iwate.jp/docs/2021101200012/file_contents/honpen.pdf | L18: 第二期雫石町環境基本計画 | M18: R3〜R10 | N18: 10 | O18: 確認済 | P18: 未確認 | Q18: https://www.town.shizukuishi.iwate.jp/docs/2016050600013/file_contents/kankyoukihonkeikaku.pdf | R18: 交通：第1次R3.5〜R6.3、第2次（R7〜R11）はパブコメR7.3.17締切で策定 https://www.town.shizukuishi.iwate.jp/docs/2025021300036/ 。環境：R3.5策定、終期は検索で未確認（10年ならR12）。 【追加調査 2026-10】環境：第二期雫石町環境基本計画（R3.5策定）、計画期間R3〜R10（2021〜2028年度、8年間）。町サイト限定検索2回の取得本文で一致して確認。中間見直し規定あり。終期R10のため次期計画の着手状況は未調査。確認日2026-10-02。URL: https://www.town.shizukuishi.iwate.jp/docs/2016050600013/file_contents/kankyoukihonkeikaku.pdf 根拠: 計画期間は2021年度（令和3年度）から2028年度（令和10年度）までの8年間（検索取得本文の要約） | S18: 調査済 | T18: 掲載
A19: 16 | B19: 葛巻町 | C19: =IF(OR(D19="◎",E19="◎"),"◎ 営業",IF(OR(D19="△",E19="△"),"△ 着手済・要確認",IF(OR(D19="？",E19="？"),"？ 期間要確認","✕ 対象外"))) | D19: =IF(J19="計画なし","－",IF(J19="策定済","✕",IF(H19="","？",IF(AND(H19>=TGT_MIN,H19<=TGT_MAX),IF(J19="着手済","△","◎"),"✕")))) | E19: =IF(P19="計画なし","－",IF(P19="策定済","✕",IF(N19="","？",IF(AND(N19>=TGT_MIN,N19<=TGT_MAX),IF(P19="着手済","△","◎"),"✕")))) | G19: 不明 | I19: 不明 | J19: 計画なし | M19: 不明 | O19: 不明 | P19: 計画なし | R19: 交通・環境とも町サイト検索で計画を確認できず（公共交通マップのみ https://www.town.kuzumaki.iwate.jp/docs/2015102200249/ ）。県の地域公共交通計画でカバーされる可能性。 | S19: 環境のみ調査 | T19: 未掲載
A20: 17 | B20: 岩手町 | C20: =IF(OR(D20="◎",E20="◎"),"◎ 営業",IF(OR(D20="△",E20="△"),"△ 着手済・要確認",IF(OR(D20="？",E20="？"),"？ 期間要確認","✕ 対象外"))) | D20: =IF(J20="計画なし","－",IF(J20="策定済","✕",IF(H20="","？",IF(AND(H20>=TGT_MIN,H20<=TGT_MAX),IF(J20="着手済","△","◎"),"✕")))) | E20: =IF(P20="計画なし","－",IF(P20="策定済","✕",IF(N20="","？",IF(AND(N20>=TGT_MIN,N20<=TGT_MAX),IF(P20="着手済","△","◎"),"✕")))) | F20: 岩手町地域公共交通計画 | G20: R4〜R8 | H20: 8 | I20: 確認済 | J20: 未確認 | K20: https://town.iwate.iwate.jp/town/gyosei/koutsuumoukeisei2017-2021/ | M20: 不明 | O20: 不明 | P20: 計画なし | R20: 交通：R4.4策定、2022〜2026年度でR8終期。県協議会資料に「令和8年度から令和12年度」との記載があり https://www.pref.iwate.jp/_res/projects/default_project/_page_/001/032/597/1127siryou5.pdf 、次期計画との関係は要確認。環境：環境基本計画は確認できず（SDGs未来都市計画あり）。 | S20: 調査済 | T20: 掲載
